Workbook
Name TítuloColuna12: #REF!
Name CategoriaDeOrçamento: #REF!
Name insumos: #REF!
Name aa: #REF!
Name TítuloColuna13: #REF!
Name rrr: #REF!
Name TítuloColuna11: #REF!
Name Pecuária: #REF!
Name Milho_Safrinha: #REF!
Name Cultura: #REF!
Name as: #REF!
Name Soja: #REF!
Name Arroz: #REF!
Name CategoriasDespesas: #REF!
Name PRINT_AREA: #REF!
Name Luiza: #REF!
Name Milho: #REF!
Name Feijão: #REF!
Name TítuloColuna6: #REF!
Name CC: #REF!
Name TítuloColuna8: #REF!
Name PGREC: #REF!
Name TítuloColuna10: #REF!
Name DOLAR: #REF!
Name LOTAÇAO2: #REF!
Name TítuloColuna7: #REF!
Name DOLAR_MES: #REF!
Name TítuloColuna2: #REF!
Name TítuloColuna4: #REF!
Name Jaim: #REF!
Name TítuloColuna5: #REF!
Name TítuloColuna3: #REF!
Name TítuloColuna9: #REF!
Name Feijão_Safrinha: #REF!
Name TítuloColuna14: #REF!
Name PRINT_AREA: #REF!
Name Pecuária: #REF!
Name LOTAÇAO2: #REF!
Name Cultura: #REF!
Name PGREC: #REF!
Name CC: #REF!
Name as: #REF!
Name Feijão: #REF!
Name Jaim: #REF!
Name Arroz: #REF!
Name Feijão_Safrinha: #REF!
Name Soja: #REF!
Name Milho: #REF!
Name Milho_Safrinha: #REF!

Sheet BANCO DE DADOS
D2: https://www.gov.br/secom/pt-br/acompanhe-a-secom/noticias/2026/01/nova-tabela-do-ir-veja-faixas-e-aliquotas-e-saiba-mais-sobre-medida-que-isenta-o-pagamento-para-quem-ganha-ate-r-5-mil
B4: TABELA DO I.R.P.F 2026
B6: I.R.P.F. | D6: Base | E6: % | F6: Dedução | G6: Dedução
B7: rendimento bruto até | D7: 28467.2 | E7: Isento | F7: 0 | G7: 0
B8: rendimento bruto até | D8: 33919.8 | E8: 0.075 | F8: 2135.04 | G8: 2135.04
B9: rendimento bruto até | D9: 45012.6 | E9: 0.15 | F9: 4679.03 | G9: 4679.03
B10: rendimento bruto até | D10: 55976.16 | E10: 0.225 | F10: 8054.97 | G10: 8054.97
B11: rendimento bruto acima | D11: 55976.16 | E11: 0.275 | F11: 10853.78 | G11: 10853.78
B13: Declaração Simplificada (Teto) | D13: 88200 | E13: 0.2 | F13: 17640 | G13: 17640
B16: DEDUÇÃO POR DEPENDENTE | E16: MÁXIMO | F16: 2275.08 | G16: 2275.08
B17: DEDUÇÃO COM INSTRUÇÃO | E17: MÁXIMO | F17: 3561.5 | G17: 3561.5
B18: PREVIDENCIA PRIVADA | E18: MÁXIMO | F18: 0.12 | G18: 0.12
B19: EMPREGADA DOMESTICA* | E19: MÁXIMO
B20: DOAÇÕES E INCENTIVOS | E20: MÁXIMO | F20: 0.06 | G20: 0.06
B22: FONTE: http://idg.receita.fazenda.gov.br/acesso-rapido/tributos/irpf-imposto-de-renda-pessoa-fisica
B28: Receitas | C28: Taxa de Redução | E28: PIS/COFINS | G28: PJ OU PF | I28: FUNRURAL PJ
B29: ARROZ COM CASCA | C29: 0.6 | E29: SIM | G29: PF | I29: FOLHA DE PAGAMENTO
B30: SOJA | C30: 0.6 | E30: NÃO | G30: PJ | I30: FATURAMENTO
B31: MILHO EM GRÃO | C31: 0.6
B32: SORGO | C32: 0.6
B33: GERGELIM | C33: 0.6
B34: ALGODÃO | C34: 0.6
B35: CAFÉ | C35: 1
B36: UVA | C36: 1
B37: BEZERRO | C37: 0.6
B38: TERNEIRO | C38: 0.6
B39: NOVILHO | C39: 0.6
B40: VACA | C40: 0.6
B41: BOI | C41: 0.6
B42: FEIJÃO | C42: 1
... B44: PEIXES EXÓTICOS | C44: 0.6

Sheet RECEITAS
C1: FAVOR NÃO EDITAR ESSE CAMPO
C2: Descrição | D2: Realizado | G2: Projetado
C3: Receitas PF | D3: =G63 | G3: =H63
C4: Receitas PJ | D4: =G64 | G4: =H64
B12: CALCIR - RECEITAS | I12: =YEAR(H14)
B13: # | G13: FUNRURAL PJ | H13: Período Inicial | I13: Período Final
G14: FATURAMENTO | H14: 46023 | I14: =(CONCATENATE("31/12/",RIGHT(H14,4)))
B16: PROJEÇÕES RECEITAS | C16: OBSERVAÇÕES | D16: PJ OU PF | E16: PIS/COFINS | F16: MÊS | G16: QUANTIDADE | H16: VALOR UNITÁRIO | I16: PROJETADO TOTAL
B17: SOJA | D17: PJ | E17: NÃO | F17: Jan | G17: 100000 | H17: 110 | I17: =IF(G17*H17=0,"",G17*H17)
I18: =IF(G18*H18=0,"",G18*H18)
I19: =IF(G19*H19=0,"",G19*H19)
I20: =IF(G20*H20=0,"",G20*H20)
I21: =IF(G21*H21=0,"",G21*H21)
I22: =IF(G22*H22=0,"",G22*H22)
I23: =IF(G23*H23=0,"",G23*H23)
I24: =IF(G24*H24=0,"",G24*H24)
I25: =IF(G25*H25=0,"",G25*H25)
I26: =IF(G26*H26=0,"",G26*H26)
B27: TOTAL DAS PROJEÇÕES DE RECEITAS | I27: =SUM(I17:I26)
G28: TOTAL PROJEÇÕES RECEITAS PF | I28: =SUMIF(D17:D26,"PF",I17:I26)
G29: TOTAL PROJEÇÕES RECEITAS PJ | I29: =SUMIF(D17:D26,"PJ",I17:I26)
B31: REALIZAÇÕES DAS RECEITAS | C31: OBSERVAÇÕES | D31: PJ OU PF | E31: PIS/COFINS | F31: MÊS | G31: QUANTIDADE | H31: VALOR UNITÁRIO | I31: PROJETADO TOTAL
I32: =IF(G32*H32=0,"",G32*H32)
B33: SOJA | D33: PJ | E33: NÃO | F33: Jan | G33: 1 | H33: 5000000 | I33: =IF(G33*H33=0,"",G33*H33)
B34: SORGO | D34: PJ | E34: NÃO | F34: Fev | G34: 1 | H34: 1000000 | I34: =IF(G34*H34=0,"",G34*H34)
B35: ARROZ COM CASCA | D35: PJ | E35: NÃO | F35: Abr | G35: 1 | H35: 1200000 | I35: =IF(G35*H35=0,"",G35*H35)
B36: CAFÉ | D36: PJ | E36: NÃO | F36: Mai | G36: 1 | H36: 1500000 | I36: =IF(G36*H36=0,"",G36*H36)
B37: GERGELIM | D37: PF | E37: NÃO | F37: Jan | G37: 1 | H37: 1000000 | I37: =IF(G37*H37=0,"",G37*H37)
I38: =IF(G38*H38=0,"",G38*H38)
I39: =IF(G39*H39=0,"",G39*H39)
I40: =IF(G40*H40=0,"",G40*H40)
I41: =IF(G41*H41=0,"",G41*H41)
B42: TOTAL RECEITAS REALIZADAS | I42: =SUM(I32:I41)
H43: TOTAL REALIZADO RECEITAS PF | I43: =SUMIF(D32:D41,"PF",I32:I41)
H44: TOTAL REALIZADO RECEITAS PJ | I44: =SUMIF(D32:D41,"PJ",I32:I41)
H46: TOTAL REALIZADO RECEITAS PF 2023
B48: VENDA DE IMOBILIZADO | D48: PJ OU PF | F48: MÊS | G48: REALIZADO | H48: PROJETADO | I48: TOTAL 2024
I49: =G49+H49
I50: =G50+H50
I51: =G51+H51
...

Sheet CAPA
E1: FAVOR NÃO EDITAR ESSE CAMPO
E2: Descrição | F2: Realizado | G2: Projetado
E3: Receitas PF | F3: =G56 | G3: =H56
E4: Receitas PJ | F4: =G57 | G4: =H57

Sheet DESPESAS
C1: FAVOR NÃO EDITAR ESSE CAMPO
B2: Operacionais | C2: =D44 | D2: =E44
B3: Imobilizado | C3: =E58 | D3: =F58
B11: CALCIR - DESPESAS E INVESTIMENTOS | G11: =RECEITAS!I12
B12: =RECEITAS!B13 | F12: Período Inicial | G12: Período Final
F13: =RECEITAS!H14 | G13: =RECEITAS!I14
B15: DESCRIÇÃO | C15: OBSERVAÇÕES | D15: REALIZADO | E15: A REALIZAR | F15: =CONCAT("TOTAL ",$G$11) | G15: =G11-1
B16: MAO DE OBRA FIXA | D16: 809962.11 | F16: =IF(D16+E16=0," ",D16+E16)
B17: MAO-DE-OBRA EVENTUAL | D17: 15920.4 | F17: =IF(D17+E17=0," ",D17+E17)
D18: 0 | F18: =IF(D18+E18=0," ",D18+E18)
D19: 0 | F19: =IF(D19+E19=0," ",D19+E19)
D20: 1000000 | F20: =IF(D20+E20=0," ",D20+E20)
D21: 0 | F21: =IF(D21+E21=0," ",D21+E21)
D22: 600000 | F22: =IF(D22+E22=0," ",D22+E22)
D23: 600000 | F23: =IF(D23+E23=0," ",D23+E23)
D24: 120000 | F24: =IF(D24+E24=0," ",D24+E24)
D25: 60000 | F25: =IF(D25+E25=0," ",D25+E25)
D26: 60000 | F26: =IF(D26+E26=0," ",D26+E26)
D27: 60000 | F27: =IF(D27+E27=0," ",D27+E27)
D28: 600000 | F28: =IF(D28+E28=0," ",D28+E28)
D29: 300000 | F29: =IF(D29+E29=0," ",D29+E29)
F30: =IF(D30+E30=0," ",D30+E30)
F31: =IF(D31+E31=0," ",D31+E31)
F32: =IF(D32+E32=0," ",D32+E32)
F33: =IF(D33+E33=0," ",D33+E33)
F34: =IF(D34+E34=0," ",D34+E34)
F35: =IF(D35+E35=0," ",D35+E35)
F36: =IF(D36+E36=0," ",D36+E36)
F37: =IF(D37+E37=0," ",D37+E37)
F38: =IF(D38+E38=0," ",D38+E38)
F39: =IF(D39+E39=0," ",D39+E39)
F40: =IF(D40+E40=0," ",D40+E40)
F41: =IF(D41+E41=0," ",D41+E41)
... F43: =IF(D43+E43=0," ",D43+E43)
B44: TOTAL DAS DESPESAS | D44: =SUM(D16:D43) | E44: =SUM(E16:E43) | F44: =SUM(F16:F43) | G44: =SUM(G16:G43)
B47: AQUISIÇÃO DE IMOBILIZADO | D47: PF OU PJ | E47: REALIZADO | F47: A REALIZAR | G47: =CONCAT("TOTAL ",$G$11)
G48: =IFERROR(E48+F48," ")
G49: =IFERROR(E49+F49," ")
G50: =IFERROR(E50+F50," ")
G51: =IFERROR(E51+F51," ")
...

Sheet PARTICULAR
B1: ATIVIDADE RURAL PARTICULAR
B6: FAVOR INFORMAR RECEITAS E DESPESAS DA ATIVIDADE RURAL DIRETA (NAO PARCERIA)
B7: 2026
A8: 1 | B8: =RESULTADO!B28 | C8: JANEIRO | D8: FEVEREIRO | E8: MARCO | F8: ABRIL | G8: MAIO | H8: JUNHO | I8: JULHO | J8: AGOSTO | K8: SETEMBRO | L8: OUTUBRO | M8: NOVEMBRO | N8: DEZEMBRO | O8: TOTAL
B9: RECEITAS | C9: 200000 | O9: =SUM(C9:N9)
B10: DESPESAS | O10: =SUM(C10:N10)
B11: RESULTADO | C11: =C9-C10 | D11: =D9-D10 | E11: =E9-E10 | F11: =F9-F10 | G11: =G9-G10 | H11: =H9-H10 | I11: =I9-I10 | J11: =J9-J10 | ... O11: =O9-O10
A12: 2 | B12: =RESULTADO!B29 | C12: JANEIRO | D12: FEVEREIRO | E12: MARCO | F12: ABRIL | G12: MAIO | H12: JUNHO | I12: JULHO | J12: AGOSTO | K12: SETEMBRO | L12: OUTUBRO | M12: NOVEMBRO | N12: DEZEMBRO | O12: TOTAL
B13: RECEITAS | O13: =SUM(C13:N13)
B14: DESPESAS | O14: =SUM(C14:N14)
B15: RESULTADO | C15: =C13-C14 | D15: =D13-D14 | E15: =E13-E14 | F15: =F13-F14 | G15: =G13-G14 | H15: =H13-H14 | I15: =I13-I14 | J15: =J13-J14 | ... O15: =O13-O14
A16: 3 | B16: =RESULTADO!B30 | C16: JANEIRO | D16: FEVEREIRO | E16: MARCO | F16: ABRIL | G16: MAIO | H16: JUNHO | I16: JULHO | J16: AGOSTO | K16: SETEMBRO | L16: OUTUBRO | M16: NOVEMBRO | N16: DEZEMBRO | O16: TOTAL
B17: RECEITAS | O17: =SUM(C17:N17)
B18: DESPESAS | O18: =SUM(C18:N18)
B19: RESULTADO | C19: =C17-C18 | D19: =D17-D18 | E19: =E17-E18 | F19: =F17-F18 | G19: =G17-G18 | H19: =H17-H18 | I19: =I17-I18 | J19: =J17-J18 | ... O19: =O17-O18
A20: 4 | B20: =RESULTADO!B31 | C20: JANEIRO | D20: FEVEREIRO | E20: MARCO | F20: ABRIL | G20: MAIO | H20: JUNHO | I20: JULHO | J20: AGOSTO | K20: SETEMBRO | L20: OUTUBRO | M20: NOVEMBRO | N20: DEZEMBRO | O20: TOTAL
B21: RECEITAS | O21: =SUM(C21:N21)
B22: DESPESAS | O22: =SUM(C22:N22)
B23: RESULTADO | C23: =C21-C22 | D23: =D21-D22 | E23: =E21-E22 | F23: =F21-F22 | G23: =G21-G22 | H23: =H21-H22 | I23: =I21-I22 | J23: =J21-J22 | ... O23: =O21-O22
A24: 5 | B24: =RESULTADO!B32 | C24: JANEIRO | D24: FEVEREIRO | E24: MARCO | F24: ABRIL | G24: MAIO | H24: JUNHO | I24: JULHO | J24: AGOSTO | K24: SETEMBRO | L24: OUTUBRO | M24: NOVEMBRO | N24: DEZEMBRO | O24: TOTAL
B25: RECEITAS | O25: =SUM(C25:N25)
B26: DESPESAS | O26: =SUM(C26:N26)
B27: RESULTADO | C27: =C25-C26 | D27: =D25-D26 | E27: =E25-E26 | F27: =F25-F26 | G27: =G25-G26 | H27: =H25-H26 | I27: =I25-I26 | J27: =J25-J26 | ... O27: =O25-O26
A28: 6 | B28: =RESULTADO!B33 | C28: JANEIRO | D28: FEVEREIRO | E28: MARCO | F28: ABRIL | G28: MAIO | H28: JUNHO | I28: JULHO | J28: AGOSTO | K28: SETEMBRO | L28: OUTUBRO | M28: NOVEMBRO | N28: DEZEMBRO | O28: TOTAL
B29: RECEITAS | O29: =SUM(C29:N29)
B30: DESPESAS | O30: =SUM(C30:N30)
B31: RESULTADO | C31: =C29-C30 | D31: =D29-D30 | E31: =E29-E30 | F31: =F29-F30 | G31: =G29-G30 | H31: =H29-H30 | I31: =I29-I30 | J31: =J29-J30 | ... O31: =O29-O30
A32: 7 | B32: =RESULTADO!B34 | C32: JANEIRO | D32: FEVEREIRO | E32: MARCO | F32: ABRIL | G32: MAIO | H32: JUNHO | I32: JULHO | J32: AGOSTO | K32: SETEMBRO | L32: OUTUBRO | M32: NOVEMBRO | N32: DEZEMBRO | O32: TOTAL
B33: RECEITAS | O33: =SUM(C33:N33)
B34: DESPESAS | O34: =SUM(C34:N34)
B35: RESULTADO | C35: =C33-C34 | D35: =D33-D34 | E35: =E33-E34 | F35: =F33-F34 | G35: =G33-G34 | H35: =H33-H34 | I35: =I33-I34 | J35: =J33-J34 | ... O35: =O33-O34
A36: 8 | B36: =RESULTADO!B35 | C36: JANEIRO | D36: FEVEREIRO | E36: MARCO | F36: ABRIL | G36: MAIO | H36: JUNHO | I36: JULHO | J36: AGOSTO | K36: SETEMBRO | L36: OUTUBRO | M36: NOVEMBRO | N36: DEZEMBRO | O36: TOTAL
B37: RECEITAS | O37: =SUM(C37:N37)
B38: DESPESAS | O38: =SUM(C38:N38)
B39: RESULTADO | C39: =C37-C38 | D39: =D37-D38 | E39: =E37-E38 | F39: =F37-F38 | G39: =G37-G38 | H39: =H37-H38 | I39: =I37-I38 | J39: =J37-J38 | ... O39: =O37-O38

Sheet REC. NAO RURAIS
B6: RENDIMENTOS E RETENÇÕES PARTICULARES | O6: =RECEITAS!I12
B7: =RECEITAS!B13
A9: 1 | B9: =RESULTADO!B28
B11: 2026 | C11: JANEIRO | D11: FEVEREIRO | E11: MARÇO | F11: ABRIL | G11: MAIO | H11: JUNHO | I11: JULHO | J11: AGOSTO | K11: SETEMBRO | L11: OUTUBRO | M11: NOVEMBRO | N11: DEZEMBRO | O11: TOTAL
B12: RENDIMENTOS | C12: =SUM(C13:C19) | D12: =SUM(D13:D19) | E12: =SUM(E13:E19) | F12: =SUM(F13:F19) | G12: =SUM(G13:G19) | H12: =SUM(H13:H19) | I12: =SUM(I13:I19) | J12: =SUM(J13:J19) | ... N12: =SUM(N13:N19) | O12: =SUM(C12:N12)
B13: DIVIDENDOS | C13: 1000000 | O13: =SUM(C13:N13)
B14: ALUGUÉIS | C14: 48000 | O14: =SUM(C14:N14)
B15: PRÓ-LABORE/RENDIMENTOS ASSALARIADOS | C15: 24000 | O15: =SUM(C15:N15)
B16: RENDIMENTOS DE APLICAÇÕES FINANCEIRAS (TRIBUTÁVEIS/CDB/AÇÕES) | O16: =SUM(C16:N16)
B17: RENDIMENTOS PROTEGIDOS (LCI/LCA/POUPANÇA)
B18: DOAÇÕES RECEBIDAS | O18: =SUM(C18:N18)
B19: GANHO DE CAPITAL (OPERAÇÕES BOLSA) | O19: =SUM(C19:N19)
B20: RETENÇÕES | C20: =SUM(C21:C25) | D20: =SUM(D21:D25) | E20: =SUM(E21:E25) | F20: =SUM(F21:F25) | G20: =SUM(G21:G25) | H20: =SUM(H21:H25) | I20: =SUM(I21:I25) | J20: =SUM(J21:J25) | ... N20: =SUM(N21:N25) | O20: =SUM(C20:N20)
B21: IRRF DIVIDENDOS | C21: =C13*0.1 | O21: =SUM(C21:N21)
B22: IRRF ALUGUÉIS | C22: 3600 | O22: =SUM(C22:N22)
B23: IRRF PRÓ-LABORE/RENDIMENTOS ASSALARIADOS | O23: =SUM(C23:N23)
B24: IRRF RENDIMENTOS DE APLICAÇÕES FINANCEIRAS | O24: =SUM(C24:N24)
B25: IRRF OPERAÇÕES BOLSA | O25: =SUM(C25:N25)
B26: RESULTADO | C26: =C12-C20 | D26: =D12-D20 | E26: =E12-E20 | F26: =F12-F20 | G26: =G12-G20 | H26: =H12-H20 | I26: =I12-I20 | J26: =J12-J20 | ... N26: =N12-N20 | O26: =SUM(C26:N26)
A29: 2 | B29: =RESULTADO!B29
B31: 2026 | C31: JANEIRO | D31: FEVEREIRO | E31: MARÇO | F31: ABRIL | G31: MAIO | H31: JUNHO | I31: JULHO | J31: AGOSTO | K31: SETEMBRO | L31: OUTUBRO | M31: NOVEMBRO | N31: DEZEMBRO | O31: TOTAL
B32: RENDIMENTOS | C32: =SUM(C33:C39) | D32: =SUM(D33:D39) | E32: =SUM(E33:E39) | F32: =SUM(F33:F39) | G32: =SUM(G33:G39) | H32: =SUM(H33:H39) | I32: =SUM(I33:I39) | J32: =SUM(J33:J39) | ... N32: =SUM(N33:N39) | O32: =SUM(C32:N32)
B33: DIVIDENDOS | O33: =SUM(C33:N33)
B34: ALUGUÉIS | O34: =SUM(C34:N34)
B35: PRÓ-LABORE/RENDIMENTOS ASSALARIADOS | O35: =SUM(C35:N35)
B36: RENDIMENTOS DE APLICAÇÕES FINANCEIRAS (TRIBUTÁVEIS/CDB/AÇÕES) | O36: =SUM(C36:N36)
B37: RENDIMENTOS PROTEGIDOS (LCI/LCA/POUPANÇA)
B38: DOAÇÕES RECEBIDAS | O38: =SUM(C38:N38)
B39: GANHO DE CAPITAL (OPERAÇÕES BOLSA) | O39: =SUM(C39:N39)
B40: RETENÇÕES | C40: =SUM(C41:C45) | D40: =SUM(D41:D45) | E40: =SUM(E41:E45) | F40: =SUM(F41:F45) | G40: =SUM(G41:G45) | H40: =SUM(H41:H45) | I40: =SUM(I41:I45) | J40: =SUM(J41:J45) | ... N40: =SUM(N41:N45) | O40: =SUM(C40:N40)
B41: IRRF DIVIDENDOS | C41: =SUMPRODUCT((C33:N33 > 50000) * (C33:N33 * 0.1)) | D41: =SUMPRODUCT((D33:O33 > 50000) * (D33:O33 * 0.1)) | E41: =SUMPRODUCT((E33:P33 > 50000) * (E33:P33 * 0.1)) | F41: =SUMPRODUCT((F33:Q33 > 50000) * (F33:Q33 * 0.1)) | G41: =SUMPRODUCT((G33:R33 > 50000) * (G33:R33 * 0.1)) | H41: =SUMPRODUCT((H33:S33 > 50000) * (H33:S33 * 0.1)) | I41: =SUMPRODUCT((I33:T33 > 50000) * (I33:T33 * 0.1)) | J41: =SUMPRODUCT((J33:U33 > 50000) * (J33:U33 * 0.1)) | ... N41: =SUMPRODUCT((N33:Y33 > 50000) * (N33:Y33 * 0.1)) | O41: =SUM(C41:N41)
B42: IRRF ALUGUÉIS | O42: =SUM(C42:N42)
B43: IRRF PRÓ-LABORE/RENDIMENTOS ASSALARIADOS | O43: =SUM(C43:N43)
B44: IRRF RENDIMENTOS DE APLICAÇÕES FINANCEIRAS | O44: =SUM(C44:N44)
B45: IRRF OPERAÇÕES BOLSA | O45: =SUM(C45:N45)
B46: RESULTADO | C46: =C32-C40 | D46: =D32-D40 | E46: =E32-E40 | F46: =F32-F40 | G46: =G32-G40 | H46: =H32-H40 | I46: =I32-I40 | J46: =J32-J40 | ... N46: =N32-N40 | O46: =SUM(C46:N46)
A47: 3 | B47: =RESULTADO!B30
B49: 2026 | C49: JANEIRO | D49: FEVEREIRO | E49: MARÇO | F49: ABRIL | G49: MAIO | H49: JUNHO | I49: JULHO | J49: AGOSTO | K49: SETEMBRO | L49: OUTUBRO | M49: NOVEMBRO | N49: DEZEMBRO | O49: TOTAL
B50: RENDIMENTOS | C50: =SUM(C51:C57) | D50: =SUM(D51:D57) | E50: =SUM(E51:E57) | F50: =SUM(F51:F57) | G50: =SUM(G51:G57) | H50: =SUM(H51:H57) | I50: =SUM(I51:I57) | J50: =SUM(J51:J57) | ... N50: =SUM(N51:N57) | O50: =SUM(C50:N50)
B51: DIVIDENDOS | O51: =SUM(C51:N51)
...

Sheet PARCERIA
B2: RECEITAS E DESPESAS PARCERIA | O2: =RECEITAS!I12
B3: =RECEITAS!B13
B5: =RECEITAS!I12 | C5: JANEIRO | D5: FEVEREIRO | E5: MARÇO | F5: ABRIL | G5: MAIO | H5: JUNHO | I5: JULHO | J5: AGOSTO | K5: SETEMBRO | L5: OUTUBRO | M5: NOVEMBRO | N5: DEZEMBRO | O5: TOTAL
B6: RECEITA | C6: =SUM(C7:C11) | D6: =SUM(D7:D11) | E6: =SUM(E7:E11) | F6: =SUM(F7:F11) | G6: =SUM(G7:G11) | H6: =SUM(H7:H11) | I6: =SUM(I7:I11) | J6: =SUM(J7:J11) | ... N6: =SUM(N7:N11) | O6: =SUM(C6:N6)
B7: SOJA
B8: ARROZ COM CASCA
B9: VACA
B10: IMOBILIZADO
B11: OUTRAS
B12: DESPESAS | C12: =SUM(C13:C14) | D12: =SUM(D13:D14) | E12: =SUM(E13:E14) | F12: =SUM(F13:F14) | G12: =SUM(G13:G14) | H12: =SUM(H13:H14) | I12: =SUM(I13:I14) | J12: =SUM(J13:J14) | ... N12: =SUM(N13:N14) | O12: =SUM(C12:N12)
B13: IMOBILIZADO | O13: =SUM(C13:N13)
B14: CUSTOS | O14: =SUM(C14:N14)
B15: RESULTADO | C15: =C6-C12 | D15: =D6-D12 | E15: =E6-E12 | F15: =F6-F12 | G15: =G6-G12 | H15: =H6-H12 | I15: =I6-I12 | J15: =J6-J12 | ... N15: =N6-N12 | O15: =SUM(C15:N15)
B16: ARBITRAMENTO | O16: =O6*20%
A19: 1 | B19: =RESULTADO!B28
C20: =RESULTADO!C28 | D20: =RESULTADO!D28
B21: =$B$5 | C21: JANEIRO | D21: FEVEREIRO | E21: MARÇO | F21: ABRIL | G21: MAIO | H21: JUNHO | I21: JULHO | J21: AGOSTO | K21: SETEMBRO | L21: OUTUBRO | M21: NOVEMBRO | N21: DEZEMBRO | O21: TOTAL
B22: RECEITA | C22: =C6*$C$20 | D22: =D6*$C$20 | E22: =E6*$C$20 | F22: =F6*$C$20 | G22: =G6*$C$20 | H22: =H6*$C$20 | I22: =I6*$C$20 | J22: =J6*$C$20 | ... N22: =N6*$C$20 | O22: =SUM(C22:N22)
B23: DESPESAS | C23: =C12*$D$20 | D23: =D12*$D$20 | E23: =E12*$D$20 | F23: =F12*$D$20 | G23: =G12*$D$20 | H23: =H12*$D$20 | I23: =I12*$D$20 | J23: =J12*$D$20 | ... N23: =N12*$D$20 | O23: =SUM(C23:N23)
B24: RESULTADO | C24: =C22-C23 | D24: =D22-D23 | E24: =E22-E23 | F24: =F22-F23 | G24: =G22-G23 | H24: =H22-H23 | I24: =I22-I23 | J24: =J22-J23 | ... N24: =N22-N23 | O24: =SUM(C24:N24)
A27: =A19+1 | B27: =RESULTADO!B29
C28: =RESULTADO!C29 | D28: =RESULTADO!D29
B29: =$B$5 | C29: JANEIRO | D29: FEVEREIRO | E29: MARÇO | F29: ABRIL | G29: MAIO | H29: JUNHO | I29: JULHO | J29: AGOSTO | K29: SETEMBRO | L29: OUTUBRO | M29: NOVEMBRO | N29: DEZEMBRO | O29: TOTAL
B30: RECEITA | C30: =C6*$C$28 | D30: =D6*$C$28 | E30: =E6*$C$28 | F30: =F6*$C$28 | G30: =G6*$C$28 | H30: =H6*$C$28 | I30: =I6*$C$28 | J30: =J6*$C$28 | ... N30: =N6*$C$28 | O30: =SUM(C30:N30)
B31: DESPESAS | C31: =C12*$D$28 | D31: =D12*$D$28 | E31: =E12*$D$28 | F31: =F12*$D$28 | G31: =G12*$D$28 | H31: =H12*$D$28 | I31: =I12*$D$28 | J31: =J12*$D$28 | ... N31: =N12*$D$28 | O31: =SUM(C31:N31)
B32: RESULTADO | C32: =C30-C31 | D32: =D30-D31 | E32: =E30-E31 | F32: =F30-F31 | G32: =G30-G31 | H32: =H30-H31 | I32: =I30-I31 | J32: =J30-J31 | ... N32: =N30-N31 | O32: =SUM(C32:N32)
A35: =A27+1 | B35: =RESULTADO!B30
C36: =RESULTADO!C30 | D36: =RESULTADO!D30
B37: =$B$5 | C37: JANEIRO | D37: FEVEREIRO | E37: MARÇO | F37: ABRIL | G37: MAIO | H37: JUNHO | I37: JULHO | J37: AGOSTO | K37: SETEMBRO | L37: OUTUBRO | M37: NOVEMBRO | N37: DEZEMBRO | O37: TOTAL
B38: RECEITA | C38: =C6*$C$36 | D38: =D6*$C$36 | E38: =E6*$C$36 | F38: =F6*$C$36 | G38: =G6*$C$36 | H38: =H6*$C$36 | I38: =I6*$C$36 | J38: =J6*$C$36 | ... N38: =N6*$C$36 | O38: =SUM(C38:N38)
B39: DESPESAS | C39: =C12*$D$36 | D39: =D12*$D$36 | E39: =E12*$D$36 | F39: =F12*$D$36 | G39: =G12*$D$36 | H39: =H12*$D$36 | I39: =I12*$D$36 | J39: =J12*$D$36 | ... N39: =N12*$D$36 | O39: =SUM(C39:N39)
B40: RESULTADO | C40: =C38-C39 | D40: =D38-D39 | E40: =E38-E39 | F40: =F38-F39 | G40: =G38-G39 | H40: =H38-H39 | I40: =I38-I39 | J40: =J38-J39 | ... N40: =N38-N39 | O40: =SUM(C40:N40)
A43: =A35+1 | B43: =RESULTADO!B31
C44: =RESULTADO!C31 | D44: =RESULTADO!D31
B45: =$B$5 | C45: JANEIRO | D45: FEVEREIRO | E45: MARÇO | F45: ABRIL | G45: MAIO | H45: JUNHO | I45: JULHO | J45: AGOSTO | K45: SETEMBRO | L45: OUTUBRO | M45: NOVEMBRO | N45: DEZEMBRO | O45: TOTAL
B46: RECEITA | C46: =C6*$C$44 | D46: =D6*$C$44 | E46: =E6*$C$44 | F46: =F6*$C$44 | G46: =G6*$C$44 | H46: =H6*$C$44 | I46: =I6*$C$44 | J46: =J6*$C$44 | ... N46: =N6*$C$44 | O46: =SUM(C46:N46)
B47: DESPESAS | C47: =C12*$D$44 | D47: =D12*$D$44 | E47: =E12*$D$44 | F47: =F12*$D$44 | G47: =G12*$D$44 | H47: =H12*$D$44 | I47: =I12*$D$44 | J47: =J12*$D$44 | ... N47: =N12*$D$44 | O47: =SUM(C47:N47)
B48: RESULTADO | C48: =C46-C47 | D48: =D46-D47 | E48: =E46-E47 | F48: =F46-F47 | G48: =G46-G47 | H48: =H46-H47 | I48: =I46-I47 | J48: =J46-J47 | ... N48: =N46-N47 | O48: =SUM(C48:N48)
A51: =A43+1 | B51: =RESULTADO!B32
C52: =RESULTADO!C32 | D52: =RESULTADO!D32
...

Sheet RESULTADO
E2: PREJUÍZO À COMPENSAR
D3: =ABS(E28) | E3: =-D3
D4: =ABS(E29) | E4: =-D4
D5: =ABS(E30) | E5: =-D5
D6: =ABS(E31) | E6: =-D6
D7: =ABS(E32) | E7: =-D7
D8: =ABS(E33) | E8: =-D8
D9: =ABS(E34) | E9: =-D9
D10: =ABS(E35) | E10: =-D10
E11: =SUM(E3:E7)
B17: CALCIR - RESULTADO | G17: =RECEITAS!I12
B18: =RECEITAS!B13 | F18: Período Inicial | G18: Período Final
F19: =RECEITAS!H14 | G19: =RECEITAS!I14
B21: RESUMO PF | D21: REALIZADO | E21: PROJETADO | F21: =G17 | G21: =F21-1
B22: RECEITAS TOTAIS | D22: =RECEITAS!G63 | E22: =RECEITAS!H63 | F22: =D22+E22 | G22: =RECEITAS!I46
B23: DESPESAS TOTAIS | D23: =DESPESAS!D44+SUMIF(DESPESAS!D48:D54,"pf",DESPESAS!E48:E54) | E23: =DESPESAS!E44+SUMIF(DESPESAS!D48:D54,"pf",DESPESAS!F48:F54) | F23: =D23+E23 | G23: =DESPESAS!G44+DESPESAS!G57
B24: RESULTADO | D24: =D22-D23 | E24: =E22-E23 | F24: =F22-F23 | G24: =G22-G23
B26: ESTRUTURA DE EXPLORAÇÃO / RESULTADO
B27: PARCEIROS | C27: % RECEITA | D27: % DESPESAS | E27: PREJUÍZO A COMPENSAR | F27: IRPF CALCULADO | G27: PREJUÍZO ACUMULADO
B28: PARCEIRO A | C28: 0.3333 | D28: =C28 | E28: 167185.35 | F28: ='RESULTADO DETALHADO'!J25 | G28: =ABS(IF('RESULTADO DETALHADO'!J20<0,'RESULTADO DETALHADO'!J20,0))
B29: PARCEIRO B | C29: 0.3333 | D29: =C29 | E29: 167186.34 | F29: ='RESULTADO DETALHADO'!J34 | G29: =ABS(IF('RESULTADO DETALHADO'!J29<0,'RESULTADO DETALHADO'!J29,0))
B30: PARCEIRO C | C30: 0.3334 | D30: =C30 | E30: 189254.39 | F30: ='RESULTADO DETALHADO'!J43 | G30: =ABS(IF('RESULTADO DETALHADO'!J38<0,'RESULTADO DETALHADO'!J38,0))
D31: =C31 | F31: ='RESULTADO DETALHADO'!J52 | G31: =ABS(IF('RESULTADO DETALHADO'!J47<0,'RESULTADO DETALHADO'!J47,0))
D32: =C32 | F32: ='RESULTADO DETALHADO'!J61 | G32: =ABS(IF('RESULTADO DETALHADO'!J56<0,'RESULTADO DETALHADO'!J56,0))
D33: =C33 | F33: ='RESULTADO DETALHADO'!J70 | G33: =ABS(IF('RESULTADO DETALHADO'!J65<0,'RESULTADO DETALHADO'!J65,0))
D34: =C34 | F34: ='RESULTADO DETALHADO'!J79 | G34: =ABS(IF('RESULTADO DETALHADO'!J74<0,'RESULTADO DETALHADO'!J74,0))
D35: =C35 | F35: ='RESULTADO DETALHADO'!J88 | G35: =ABS(IF('RESULTADO DETALHADO'!J83<0,'RESULTADO DETALHADO'!J83,0))
C36: =SUM(C28:C35) | D36: =SUM(D28:D35) | E36: =SUM(E28:E32) | F36: =SUM(F28:F34) | G36: =SUM(G28:G34)
B38: PESSOA JURÍDICA
B39: RECEITAS TOTAIS | G39: =RECEITAS!I64
B40: DESPESAS TOTAIS | G40: =DESPESAS!G59
B42: IMPOSTOS PJ
B43: IMPOSTOS | D43: FUNRURAL* | E43: IRPJ/CSLL | F43: TOTAL
B44: 2024 - PJ | D44: =PJ!G28 | E44: ='Cálculo Imposto PJ'!K21+'Cálculo Imposto PJ'!N21 | F44: =D44+E44
B45: =B42 | F45: =SUM(F44)
B46: =IF(RECEITAS!G14="FOLHA DE PAGAMENTO","Não tem cobrança de Funrural devido a opção de contribuição previdenciaria ser por Folha de Pagamento","")
B48: IMPOSTO INDIVIDUAL
B49: PARCEIROS | C49: PERCENTUAL | D49: ="PREJUÍZO A COMPENSAR " & G17-1 | E49: ="RECEITA " & G17 | F49: ="DESPESA " & G17 | G49: ="PREJUÍZO ACUMULADO PARA " & G17+1
B50: =B28 | C50: =C28 | D50: =E28 | E50: =$F$22*C50 | F50: =$F$23*C50 | G50: =G28 | I50: =IF(D50>=(E50-F50),E50-F50,D50)
B51: =B29 | C51: =C29 | D51: =E29 | E51: =$F$22*C51 | F51: =$F$23*C51 | G51: =G29 | I51: =IF(D51>=(E51-F51),E51-F51,D51)
...

Sheet RESULTADO DETALHADO
B6: CALCIR - RESULTADO DETALHADO | J6: =RECEITAS!I12
B7: =RECEITAS!B13
B12: MOVIMENTAÇÃO | D12: REALIZADO | F12: PROJETADO | I12: TOTAL
B13: RECEITAS | D13: =RESULTADO!D22 | F13: =RESULTADO!E22 | I13: =SUM(D13:H13)
B14: DESPESAS | D14: =RESULTADO!D23 | F14: =RESULTADO!E23 | I14: =SUM(D14:H14)
B15: RESULTADO | D15: =D13-D14 | F15: =F13-F14 | I15: =SUM(D15:H15)
B16: CONTA PJ | D16: 0 | E16: 0 | F16: =E16*D16
A20: 1 | B20: =RESULTADO!B28 | C20: APURAÇÃO | E20: PARTICULAR | F20: TOTAL | H20: =IF(F24=J20,"Base de Cálculo p/ Arbitramento", "Base de Cálculo p/ Resultado") | J20: =IF(AND(F23+E25>F24,F24>0),F24,F23+E25) | L20: COMPLETA | M20: SIMPLIFICADA
A21: =IF(RESULTADO!C28>0,1,0) | B21: RECEITAS | C21: =RESULTADO!C28 | D21: =($I$13*$C$21) | E21: =PARTICULAR!O9 | F21: =D21+E21 | H21: Base de Cálculo Simplificado | J21: =IF(AND(F23>F24,F24>0),F24,F23) | L21: =J23 | M21: =IF(M22*0.2<'BANCO DE DADOS'!$F$13,M22*0.2,'BANCO DE DADOS'!$F$13)
B22: DESPESAS | C22: =RESULTADO!D28 | D22: =($I$14*$C$22) | E22: =PARTICULAR!O10 | F22: =D22+E22 | H22: Dedução Simplificada | J22: =IF(J21>'BANCO DE DADOS'!D13,'BANCO DE DADOS'!F13,IF('RESULTADO DETALHADO'!J21<0,0,'RESULTADO DETALHADO'!J21*'BANCO DE DADOS'!E13)) | L22: =IF(AND(F23+E25>F24,F24>0),F24,F23+E25) | M22: =IF(AND(F23>F24,F24>0),F24,F23)
B23: RESULTADO | D23: =D21-D22 | E23: =E21-E22 | F23: =F21-F22 | H23: Dedução Completa | L23: =L22-L21 | M23: =M22-M21
B24: =IF(F24>0,"ARBITRAMENTO",0) | F24: =IF(F21*0.2>F23,0,F21*0.2) | H24: Base Tributável p/ Cálculo I.R. | J24: =IF(J20-J23<J20-J22,J20-J23,J20-J22) | L24: =IF(L23>'BANCO DE DADOS'!$D$9,((L23*'BANCO DE DADOS'!$E$10)-'BANCO DE DADOS'!$F$10),IF(L23>'BANCO DE DADOS'!$D$8,((L23*'BANCO DE DADOS'!$E$9)-'BANCO DE DADOS'!$F$9),IF(L23>'BANCO DE DADOS'!$D$7,((L23*'BANCO DE DADOS'!$E$8)-'BANCO DE DADOS'!$F$8),IF(L23>'BANCO DE DADOS'!$D$6,((L23*'BANCO DE DADOS'!$E$7)-'BANCO DE DADOS'!$F$7),0)))) | M24: =IF(M23>'BANCO DE DADOS'!$D$9,((M23*'BANCO DE DADOS'!$E$10)-'BANCO DE DADOS'!$F$10),IF(M23>'BANCO DE DADOS'!$D$8,((M23*'BANCO DE DADOS'!$E$9)-'BANCO DE DADOS'!$F$9),IF(M23>'BANCO DE DADOS'!$D$7,((M23*'BANCO DE DADOS'!$E$8)-'BANCO DE DADOS'!$F$8),IF(M23>'BANCO DE DADOS'!$D$6,((M23*'BANCO DE DADOS'!$E$7)-'BANCO DE DADOS'!$F$7),0))))
B25: PREJUÍZO ACUMULADO | E25: =RESULTADO!E3 | H25: =IF(J25>0,"Imposto Apurado","Não Houve Imposto") | J25: =IF(J24>'BANCO DE DADOS'!$D$10,(('RESULTADO DETALHADO'!J24*'BANCO DE DADOS'!$E$11)-'BANCO DE DADOS'!$F$11),IF(J24>'BANCO DE DADOS'!$D$9,(('RESULTADO DETALHADO'!J24*'BANCO DE DADOS'!$E$10)-'BANCO DE DADOS'!$F$10),IF(J24>'BANCO DE DADOS'!$D$8,(('RESULTADO DETALHADO'!J24*'BANCO DE DADOS'!$E$9)-'BANCO DE DADOS'!$F$9),IF(J24>'BANCO DE DADOS'!$D$7,(('RESULTADO DETALHADO'!J24*'BANCO DE DADOS'!$E$8)-'BANCO DE DADOS'!$F$8),0))))
H26: =IF(J20>J21,"APURAÇÃO POR BASE RESULTADO PRESUMIDO", "APURAÇÃO POR BASE RESULTADO")
F27: =F24
A29: =A20+1 | B29: =RESULTADO!B29 | C29: APURAÇÃO | E29: PARTICULAR | F29: TOTAL | H29: =IF(F33=J29,"Base de Cálculo p/ Arbitramento", "Base de Cálculo p/ Resultado") | J29: =IF(AND(F32+E34>F33,F33>0),F33,F32+E34) | L29: COMPLETA | M29: SIMPLIFICADA
A30: =IF(RESULTADO!C29>0,1,0) | B30: RECEITAS | C30: =RESULTADO!C29 | D30: =(I13*$C$30) | E30: =PARTICULAR!O13 | F30: =D30+E30 | H30: Base de Cálculo Simplificado | J30: =IF(AND(F32>F33,F33>0),F33,F32) | L30: =J32 | M30: =IF(M31*0.2<'BANCO DE DADOS'!$F$13,M31*0.2,'BANCO DE DADOS'!$F$13)
B31: DESPESAS | C31: =RESULTADO!D29 | D31: =(I14*$C$31) | E31: =PARTICULAR!O14 | F31: =D31+E31 | H31: Dedução Simplificada | J31: =IF(J30>'BANCO DE DADOS'!D13,'BANCO DE DADOS'!F13,IF('RESULTADO DETALHADO'!J30<0,0,'RESULTADO DETALHADO'!J30*'BANCO DE DADOS'!E13)) | L31: =IF(AND(F32+E34>F33,F33>0),F33,F32+E34) | M31: =IF(AND(F32>F33,F33>0),F33,F32)
B32: RESULTADO | D32: =D30-D31 | E32: =E30-E31 | F32: =F30-F31 | H32: Dedução Completa | L32: =L31-L30 | M32: =M31-M30
B33: =IF(F33>0,"ARBITRAMENTO",0) | F33: =IF(F30*0.2>F32,0,F30*0.2) | H33: Base Tributável p/ Cálculo I.R. | J33: =IF(J29-J32<J29-J31,J29-J32,J29-J31) | L33: =IF(L32>'BANCO DE DADOS'!$D$9,((L32*'BANCO DE DADOS'!$E$10)-'BANCO DE DADOS'!$F$10),IF(L32>'BANCO DE DADOS'!$D$8,((L32*'BANCO DE DADOS'!$E$9)-'BANCO DE DADOS'!$F$9),IF(L32>'BANCO DE DADOS'!$D$7,((L32*'BANCO DE DADOS'!$E$8)-'BANCO DE DADOS'!$F$8),IF(L32>'BANCO DE DADOS'!$D$6,((L32*'BANCO DE DADOS'!$E$7)-'BANCO DE DADOS'!$F$7),0)))) | M33: =IF(M32>'BANCO DE DADOS'!$D$9,((M32*'BANCO DE DADOS'!$E$10)-'BANCO DE DADOS'!$F$10),IF(M32>'BANCO DE DADOS'!$D$8,((M32*'BANCO DE DADOS'!$E$9)-'BANCO DE DADOS'!$F$9),IF(M32>'BANCO DE DADOS'!$D$7,((M32*'BANCO DE DADOS'!$E$8)-'BANCO DE DADOS'!$F$8),IF(M32>'BANCO DE DADOS'!$D$6,((M32*'BANCO DE DADOS'!$E$7)-'BANCO DE DADOS'!$F$7),0))))
B34: PREJUÍZO ACUMULADO | E34: =RESULTADO!E4 | H34: =IF(J34>0,"Imposto Apurado","Não Houve Imposto") | J34: =IF(J33>'BANCO DE DADOS'!$D$10,(('RESULTADO DETALHADO'!J33*'BANCO DE DADOS'!$E$11)-'BANCO DE DADOS'!$F$11),IF(J33>'BANCO DE DADOS'!$D$9,(('RESULTADO DETALHADO'!J33*'BANCO DE DADOS'!$E$10)-'BANCO DE DADOS'!$F$10),IF(J33>'BANCO DE DADOS'!$D$8,(('RESULTADO DETALHADO'!J33*'BANCO DE DADOS'!$E$9)-'BANCO DE DADOS'!$F$9),IF(J33>'BANCO DE DADOS'!$D$7,(('RESULTADO DETALHADO'!J33*'BANCO DE DADOS'!$E$8)-'BANCO DE DADOS'!$F$8),0))))
H35: =IF(J29>J30,"APURAÇÃO POR BASE RESULTADO PRESUMIDO", "APURAÇÃO POR BASE RESULTADO")
A38: =A29+1 | B38: =RESULTADO!B30 | C38: APURAÇÃO | E38: PARTICULAR | F38: TOTAL | H38: =IF(F42=J38,"Base de Cálculo p/ Arbitramento", "Base de Cálculo p/Resultado") | J38: =IF(AND(F41+E43>F42,F42>0),F42,F41+E43) | L38: COMPLETA | M38: SIMPLIFICADA
A39: =IF(RESULTADO!C30>0,1,0) | B39: RECEITAS | C39: =RESULTADO!C30 | D39: =(I13*$C$39) | E39: =PARTICULAR!O17 | F39: =D39+E39 | H39: Base de Cálculo Simplificado | J39: =IF(AND(F41>F42,F42>0),F42,F41) | L39: =J41 | M39: =IF(M40*0.2<'BANCO DE DADOS'!$F$13,M40*0.2,'BANCO DE DADOS'!$F$13)
B40: DESPESAS | C40: =RESULTADO!D30 | D40: =(I14*$C$40) | E40: =PARTICULAR!O18 | F40: =D40+E40 | H40: Dedução Simplificada | J40: =IF(J39>'BANCO DE DADOS'!D13,'BANCO DE DADOS'!F13,IF('RESULTADO DETALHADO'!J39<0,0,'RESULTADO DETALHADO'!J39*'BANCO DE DADOS'!E13)) | L40: =IF(AND(F41+E43>F42,F42>0),F42,F41+E43) | M40: =IF(AND(F41>F42,F42>0),F42,F41)
B41: RESULTADO | D41: =D39-D40 | E41: =E39-E40 | F41: =F39-F40 | H41: Dedução Completa | L41: =L40-L39 | M41: =M40-M39
B42: =IF(F42>0,"ARBITRAMENTO",0) | F42: =IF(F39*0.2>F41,0,F39*0.2) | H42: Base Tributável p/ Cálculo I.R. | J42: =IF(J38-J41<J38-J40,J38-J41,J38-J40) | L42: =IF(L41>'BANCO DE DADOS'!$D$9,((L41*'BANCO DE DADOS'!$E$10)-'BANCO DE DADOS'!$F$10),IF(L41>'BANCO DE DADOS'!$D$8,((L41*'BANCO DE DADOS'!$E$9)-'BANCO DE DADOS'!$F$9),IF(L41>'BANCO DE DADOS'!$D$7,((L41*'BANCO DE DADOS'!$E$8)-'BANCO DE DADOS'!$F$8),IF(L41>'BANCO DE DADOS'!$D$6,((L41*'BANCO DE DADOS'!$E$7)-'BANCO DE DADOS'!$F$7),0)))) | M42: =IF(M41>'BANCO DE DADOS'!$D$9,((M41*'BANCO DE DADOS'!$E$10)-'BANCO DE DADOS'!$F$10),IF(M41>'BANCO DE DADOS'!$D$8,((M41*'BANCO DE DADOS'!$E$9)-'BANCO DE DADOS'!$F$9),IF(M41>'BANCO DE DADOS'!$D$7,((M41*'BANCO DE DADOS'!$E$8)-'BANCO DE DADOS'!$F$8),IF(M41>'BANCO DE DADOS'!$D$6,((M41*'BANCO DE DADOS'!$E$7)-'BANCO DE DADOS'!$F$7),0))))
B43: PREJUÍZO ACUMULADO | E43: =RESULTADO!E5 | H43: =IF(J43>0,"Imposto Apurado","Não Houve Imposto") | J43: =IF(J42>'BANCO DE DADOS'!$D$10,(('RESULTADO DETALHADO'!J42*'BANCO DE DADOS'!$E$11)-'BANCO DE DADOS'!$F$11),IF(J42>'BANCO DE DADOS'!$D$9,(('RESULTADO DETALHADO'!J42*'BANCO DE DADOS'!$E$10)-'BANCO DE DADOS'!$F$10),IF(J42>'BANCO DE DADOS'!$D$8,(('RESULTADO DETALHADO'!J42*'BANCO DE DADOS'!$E$9)-'BANCO DE DADOS'!$F$9),IF(J42>'BANCO DE DADOS'!$D$7,(('RESULTADO DETALHADO'!J42*'BANCO DE DADOS'!$E$8)-'BANCO DE DADOS'!$F$8),0))))
H44: =IF(J38>J39,"APURAÇÃO POR BASE RESULTADO PRESUMIDO", "APURAÇÃO POR BASE RESULTADO")
A47: =A38+1 | B47: =RESULTADO!B31 | C47: APURAÇÃO | E47: PARTICULAR | F47: TOTAL | H47: =IF(F51=J47,"Base de Cálculo p/ Arbitramento", "Base de Cálculo p/ Resultado") | J47: =IF(AND(F50+E52>F51,F51>0),F51,F50+E52) | L47: COMPLETA | M47: SIMPLIFICADA
A48: =IF(RESULTADO!C31>0,1,0) | B48: RECEITAS | C48: =RESULTADO!C31 | D48: =($I$13*$C$48) | E48: =PARTICULAR!O21 | F48: =D48+E48 | H48: Base de Cálculo Simplificado | J48: =IF(AND(F50>F51,F51>0),F51,F50) | L48: =J50 | M48: =IF(M49*0.2<'BANCO DE DADOS'!$F$13,M49*0.2,'BANCO DE DADOS'!$F$13)
B49: DESPESAS | C49: =RESULTADO!D31 | D49: =($I$14*$C$49) | E49: =PARTICULAR!O22 | F49: =D49+E49 | H49: Dedução Simplificada | J49: =IF(J48>'BANCO DE DADOS'!D13,'BANCO DE DADOS'!F13,IF('RESULTADO DETALHADO'!J48<0,0,'RESULTADO DETALHADO'!J48*'BANCO DE DADOS'!E13)) | L49: =IF(AND(F50+E52>F51,F51>0),F51,F50+E52) | M49: =IF(AND(F50>F51,F51>0),F51,F50)
B50: RESULTADO | D50: =D48-D49 | E50: =E48-E49 | F50: =F48-F49 | H50: Dedução Completa | L50: =L49-L48 | M50: =M49-M48
B51: =IF(F51>0,"ARBITRAMENTO",0) | F51: =IF(F48*0.2>F50,0,F48*0.2) | H51: Base Tributável p/ Cálculo I.R. | J51: =IF(J47-J50<J47-J49,J47-J50,J47-J49) | L51: =IF(L50>'BANCO DE DADOS'!$D$9,((L50*'BANCO DE DADOS'!$E$10)-'BANCO DE DADOS'!$F$10),IF(L50>'BANCO DE DADOS'!$D$8,((L50*'BANCO DE DADOS'!$E$9)-'BANCO DE DADOS'!$F$9),IF(L50>'BANCO DE DADOS'!$D$7,((L50*'BANCO DE DADOS'!$E$8)-'BANCO DE DADOS'!$F$8),IF(L50>'BANCO DE DADOS'!$D$6,((L50*'BANCO DE DADOS'!$E$7)-'BANCO DE DADOS'!$F$7),0)))) | M51: =IF(M50>'BANCO DE DADOS'!$D$9,((M50*'BANCO DE DADOS'!$E$10)-'BANCO DE DADOS'!$F$10),IF(M50>'BANCO DE DADOS'!$D$8,((M50*'BANCO DE DADOS'!$E$9)-'BANCO DE DADOS'!$F$9),IF(M50>'BANCO DE DADOS'!$D$7,((M50*'BANCO DE DADOS'!$E$8)-'BANCO DE DADOS'!$F$8),IF(M50>'BANCO DE DADOS'!$D$6,((M50*'BANCO DE DADOS'!$E$7)-'BANCO DE DADOS'!$F$7),0))))
B52: PREJUÍZO ACUMULADO | E52: =RESULTADO!E6 | H52: =IF(J52>0,"Imposto Apurado","Não Houve Imposto") | J52: =IF(J51>'BANCO DE DADOS'!$D$10,(('RESULTADO DETALHADO'!J51*'BANCO DE DADOS'!$E$11)-'BANCO DE DADOS'!$F$11),IF(J51>'BANCO DE DADOS'!$D$9,(('RESULTADO DETALHADO'!J51*'BANCO DE DADOS'!$E$10)-'BANCO DE DADOS'!$F$10),IF(J51>'BANCO DE DADOS'!$D$8,(('RESULTADO DETALHADO'!J51*'BANCO DE DADOS'!$E$9)-'BANCO DE DADOS'!$F$9),IF(J51>'BANCO DE DADOS'!$D$7,(('RESULTADO DETALHADO'!J51*'BANCO DE DADOS'!$E$8)-'BANCO DE DADOS'!$F$8),0))))
H53: =IF(J47>J48,"APURAÇÃO POR BASE RESULTADO PRESUMIDO", "APURAÇÃO POR BASE RESULTADO")
A56: =A47+1 | B56: =RESULTADO!B32 | C56: APURAÇÃO | E56: PARTICULAR | F56: TOTAL | H56: =IF(F60=J56,"Base de Cálculo p/ Arbitramento", "Base de Cálculo p/ Resultado") | J56: =IF(AND(F59+E61>F60,F60>0),F60,F59+E61) | L56: COMPLETA | M56: SIMPLIFICADA
A57: =IF(RESULTADO!C32>0,1,0) | B57: RECEITAS | C57: =RESULTADO!C32 | D57: =($I$13*$C$57) | E57: =PARTICULAR!O25 | F57: =D57+E57 | H57: Base de Cálculo Simplificado | J57: =IF(AND(F59>F60,F60>0),F60,F59) | L57: =J59 | M57: =IF(M58*0.2<'BANCO DE DADOS'!$F$13,M58*0.2,'BANCO DE DADOS'!$F$13)
B58: DESPESAS | C58: =RESULTADO!D32 | D58: =($I$14*$C$58) | E58: =PARTICULAR!O26 | F58: =D58+E58 | H58: Dedução Simplificada | J58: =IF(J57>'BANCO DE DADOS'!D13,'BANCO DE DADOS'!F13,IF('RESULTADO DETALHADO'!J57<0,0,'RESULTADO DETALHADO'!J57*'BANCO DE DADOS'!E13)) | L58: =IF(AND(F59+E61>F60,F60>0),F60,F59+E61) | M58: =IF(AND(F59>F60,F60>0),F60,F59)
B59: RESULTADO | D59: =D57-D58 | E59: =E57-E58 | F59: =F57-F58 | H59: Dedução Completa | L59: =L58-L57 | M59: =M58-M57
...

Sheet PJ
B4: CALCIR - PESSOA JURÍDICA | G4: =RECEITAS!I12
B5: =RECEITAS!B13
F6: Período Analisado | G6: 12
B9: TOTAL PROJETADO (s/ PIS e COFINS) | G9: =SUMIFS(RECEITAS!$I$17:$I$26, RECEITAS!$E$17:$E$26,"NÃO", RECEITAS!$D$17:$D$26,"PJ")
B10: TOTAL REALIZADO (s/ PIS e COFINS) | G10: =SUMIFS(RECEITAS!$I$32:$I$41,RECEITAS!$E$32:$E$41,"NÃO", RECEITAS!$D$32:$D$41, "PJ")
B11: TOTAL (s/PIS e COFINS) | G11: =G9+G10
B12: TOTAL PROJETADO (c/ PIS e COFINS) | G12: =SUMIFS(RECEITAS!$I$17:$I$26, RECEITAS!$E$17:$E$26,"SIM", RECEITAS!$D$17:$D$26,"PJ")
B13: TOTAL REALIZADO (c/ PIS e COFINS) | G13: =SUMIFS(RECEITAS!$I$32:$I$41,RECEITAS!$E$32:$E$41,"SIM", RECEITAS!$D$32:$D$41, "PJ")
B14: TOTAL (c/PIS e COFINS) | G14: =G12+G13
B15: RECEITAS ALUGUÉIS (c/ CNAE)
B16: RECEITAS ALUGUÉIS (s/ CNAE)
B17: RECEITAS FINANCEIRAS
B18: RECEITAS NÃO OPERACIONAIS
B20: SIMULAÇÃO DE VALORES | G20: =RECEITAS!I26
B23: BASE DE CALCULO IR | G23: =((G11+G14)*0.08)+(G15*0.32)+G16+G17+G18
B24: BASE DE CÁLCULO CSLL | G24: =((G11+G14)*0.12)+(G15*0.32)+G16+G17+G18
B25: IR - 15% (1,20%) | G25: =G23*0.15
B26: IR ADICIONAL - 10% (0,8%) | G26: =IF(G23>G6*20000,(G23-G6*20000)*0.1,0)
B27: CSLL - 9% (1,08%) | G27: =G24*0.09
B28: FUNRURAL - 2,05% | G28: =IF(RECEITAS!G14="FATURAMENTO", (PJ!G11+PJ!G14)*2.05/100,0)
B29: PIS | G29: =(G14+G15)*0.65/100
B30: COFINS | G30: =(G14+G15)*3/100
B32: DIFERENÇA DE FUNRURAL - 0,55% | G32: =IF(RECEITAS!G14="FATURAMENTO", (PJ!G11+PJ!G14)*0.55/100,0)
B34: TOTAL TRIBUTOS PJ | G34: =IF(G6=0,"ERRO",SUM(G25:G30))
B36: TOTAL PJ + DIFERENÇA FUNRURAL | G36: =IF(G6=0,"ERRO",SUM(G25:G27,G29:G30,G32))
I39: =IF(D39>=(E39-F39),E39-F39,D39)
I40: =IF(D40>=(E40-F40),E40-F40,D40)
I41: =IF(D41>=(E41-F41),E41-F41,D41)
I42: =IF(D42>=(E42-F42),E42-F42,D42)
I43: =IF(D43>=(E43-F43),E43-F43,D43)
I44: =IF(D44>=(E44-F44),E44-F44,D44)
I45: =SUM(I39:I44)

Sheet IRPFM
C4: RESULTADO X DISTRIBUIÇÃO DE DIVIDENDOS
C5: RECEITA PJ 2026 | E5: =RECEITAS!G64
C6: IMPOSTO PJ 2026 | E6: =RESULTADO!F44
C7: OUTRAS RECEITAS
C8: DEMAIS DESPESAS | E8: 100000
C9: DIVIDENDOS A DISTRIBUIR | E9: =E5-E6-E8+E7
C10: LUCRO ACUMULADO ATÉ 2025 | E10: 0
C11: DIVIDENDOS TRIBUTÁVEL | E11: =E9-E10
C13: PARCEIROS | D13: % | E13: DISTRIBUIÇÃO TRIBUTÁVEL
C14: =RESULTADO!B28 | D14: =RESULTADO!C28 | E14: =IF($E$11*D14>0,$E$11*D14,0)
C15: =RESULTADO!B29 | D15: =RESULTADO!C29 | E15: =IF($E$11*D15>0,$E$11*D15,0)
C16: =RESULTADO!B30 | D16: =RESULTADO!C30 | E16: =IF($E$11*D16>0,$E$11*D16,0)
C17: =RESULTADO!B31 | D17: =RESULTADO!C31 | E17: =IF($E$11*D17>0,$E$11*D17,0)
C18: =RESULTADO!B32 | D18: =RESULTADO!C32 | E18: =IF($E$11*D18>0,$E$11*D18,0)
C19: =RESULTADO!B33 | D19: =RESULTADO!C33 | E19: =IF($E$11*D19>0,$E$11*D19,0)
C20: =RESULTADO!B34 | D20: =RESULTADO!C34 | E20: =IF($E$11*D20>0,$E$11*D20,0)
C21: =RESULTADO!B35 | D21: =RESULTADO!C35 | E21: =IF($E$11*D21>0,$E$11*D21,0)
C22: TOTAL | D22: =SUM(D14:D21) | E22: =SUM(E14:E21)
B24: Renda Global Real | C24: PARCEIROS | D24: ALÍQUOTA | E24: CÁLCULO | F24: IMPOSTO DEVIDO
B25: =E14 + IF('RESULTADO DETALHADO'!B24 = "ARBITRAMENTO",'RESULTADO DETALHADO'!D21 * 0.2, MAX(0,'RESULTADO DETALHADO'!D23 - RESULTADO!G50)) + PARTICULAR!O9 | C25: =C14 | D25: =IF(B25 < 600000, 0, IF(B25 > 1200000, 10%, ((B25/60000)-10)/100)) | E25: =B25*D25 | F25: =MAX(E25,MIN(IF(MAX(0,B25-MIN(B25*0.2,17640))<=28467.2,0,IF(MAX(0,B25-MIN(B25*0.2,17640))<=33919.8,MAX(0,B25-MIN(B25*0.2,17640))*0.075-2135.04,IF(MAX(0,B25-MIN(B25*0.2,17640))<=45012.6,MAX(0,B25-MIN(B25*0.2,17640))*0.15-4679.03,IF(MAX(0,B25-MIN(B25*0.2,17640))<=55976.16,MAX(0,B25-MIN(B25*0.2,17640))*0.225-8054.97,MAX(0,B25-MIN(B25*0.2,17640))*0.275-10853.78)))),IF(B25<=28467.2,0,IF(B25<=33919.8,B25*0.075-2135.04,IF(B25<=45012.6,B25*0.15-4679.03,IF(B25<=55976.16,B25*0.225-8054.97,B25*0.275-10853.78))))))
B26: =E15 + IF('RESULTADO DETALHADO'!B33 = "ARBITRAMENTO",'RESULTADO DETALHADO'!D30 * 0.2, MAX(0,'RESULTADO DETALHADO'!D32 - RESULTADO!G51)) + PARTICULAR!O13 | C26: =C15 | D26: =IF(B26 < 600000, 0, IF(B26 > 1200000, 10%, ((B26/60000)-10)/100)) | E26: =B26*D26 | F26: =MAX(E26,MIN(IF(MAX(0,B26-MIN(B26*0.2,17640))<=28467.2,0,IF(MAX(0,B26-MIN(B26*0.2,17640))<=33919.8,MAX(0,B26-MIN(B26*0.2,17640))*0.075-2135.04,IF(MAX(0,B26-MIN(B26*0.2,17640))<=45012.6,MAX(0,B26-MIN(B26*0.2,17640))*0.15-4679.03,IF(MAX(0,B26-MIN(B26*0.2,17640))<=55976.16,MAX(0,B26-MIN(B26*0.2,17640))*0.225-8054.97,MAX(0,B26-MIN(B26*0.2,17640))*0.275-10853.78)))),IF(B26<=28467.2,0,IF(B26<=33919.8,B26*0.075-2135.04,IF(B26<=45012.6,B26*0.15-4679.03,IF(B26<=55976.16,B26*0.225-8054.97,B26*0.275-10853.78))))))
B27: =E16 + IF('RESULTADO DETALHADO'!B42 = "ARBITRAMENTO",'RESULTADO DETALHADO'!D39 * 0.2, MAX(0,'RESULTADO DETALHADO'!D41 - RESULTADO!G52)) + PARTICULAR!O21 | C27: =C16 | D27: =IF(B27 < 600000, 0, IF(B27 > 1200000, 10%, ((B27/60000)-10)/100)) | E27: =B27*D27 | F27: =MAX(E27,MIN(IF(MAX(0,B27-MIN(B27*0.2,17640))<=28467.2,0,IF(MAX(0,B27-MIN(B27*0.2,17640))<=33919.8,MAX(0,B27-MIN(B27*0.2,17640))*0.075-2135.04,IF(MAX(0,B27-MIN(B27*0.2,17640))<=45012.6,MAX(0,B27-MIN(B27*0.2,17640))*0.15-4679.03,IF(MAX(0,B27-MIN(B27*0.2,17640))<=55976.16,MAX(0,B27-MIN(B27*0.2,17640))*0.225-8054.97,MAX(0,B27-MIN(B27*0.2,17640))*0.275-10853.78)))),IF(B27<=28467.2,0,IF(B27<=33919.8,B27*0.075-2135.04,IF(B27<=45012.6,B27*0.15-4679.03,IF(B27<=55976.16,B27*0.225-8054.97,B27*0.275-10853.78))))))
B28: =E17 + IF('RESULTADO DETALHADO'!B51 = "ARBITRAMENTO",'RESULTADO DETALHADO'!D48 * 0.2, MAX(0,'RESULTADO DETALHADO'!D50 - RESULTADO!G53)) + PARTICULAR!O21 | C28: =C17 | D28: =IF(B28 < 600000, 0, IF(B28 > 1200000, 10%, ((B28/60000)-10)/100)) | E28: =B28*D28 | F28: =MAX(E28,MIN(IF(MAX(0,B28-MIN(B28*0.2,17640))<=28467.2,0,IF(MAX(0,B28-MIN(B28*0.2,17640))<=33919.8,MAX(0,B28-MIN(B28*0.2,17640))*0.075-2135.04,IF(MAX(0,B28-MIN(B28*0.2,17640))<=45012.6,MAX(0,B28-MIN(B28*0.2,17640))*0.15-4679.03,IF(MAX(0,B28-MIN(B28*0.2,17640))<=55976.16,MAX(0,B28-MIN(B28*0.2,17640))*0.225-8054.97,MAX(0,B28-MIN(B28*0.2,17640))*0.275-10853.78)))),IF(B28<=28467.2,0,IF(B28<=33919.8,B28*0.075-2135.04,IF(B28<=45012.6,B28*0.15-4679.03,IF(B28<=55976.16,B28*0.225-8054.97,B28*0.275-10853.78))))))
B29: =E18 + IF('RESULTADO DETALHADO'!B60 = "ARBITRAMENTO",'RESULTADO DETALHADO'!D57 * 0.2, MAX(0,'RESULTADO DETALHADO'!D59 - RESULTADO!G54)) + PARTICULAR!O25 | C29: =C18 | D29: =IF(B29 < 600000, 0, IF(B29 > 1200000, 10%, ((B29/60000)-10)/100)) | E29: =B29*D29 | F29: =MAX(E29,MIN(IF(MAX(0,B29-MIN(B29*0.2,17640))<=28467.2,0,IF(MAX(0,B29-MIN(B29*0.2,17640))<=33919.8,MAX(0,B29-MIN(B29*0.2,17640))*0.075-2135.04,IF(MAX(0,B29-MIN(B29*0.2,17640))<=45012.6,MAX(0,B29-MIN(B29*0.2,17640))*0.15-4679.03,IF(MAX(0,B29-MIN(B29*0.2,17640))<=55976.16,MAX(0,B29-MIN(B29*0.2,17640))*0.225-8054.97,MAX(0,B29-MIN(B29*0.2,17640))*0.275-10853.78)))),IF(B29<=28467.2,0,IF(B29<=33919.8,B29*0.075-2135.04,IF(B29<=45012.6,B29*0.15-4679.03,IF(B29<=55976.16,B29*0.225-8054.97,B29*0.275-10853.78))))))
B30: =E19 + IF('RESULTADO DETALHADO'!B69 = "ARBITRAMENTO",'RESULTADO DETALHADO'!D66 * 0.2, MAX(0,'RESULTADO DETALHADO'!D68 - RESULTADO!G55)) + PARTICULAR!O29 | C30: =C19 | D30: =IF(B30 < 600000, 0, IF(B30 > 1200000, 10%, ((B30/60000)-10)/100)) | E30: =B30*D30 | F30: =MAX(E30,MIN(IF(MAX(0,B30-MIN(B30*0.2,17640))<=28467.2,0,IF(MAX(0,B30-MIN(B30*0.2,17640))<=33919.8,MAX(0,B30-MIN(B30*0.2,17640))*0.075-2135.04,IF(MAX(0,B30-MIN(B30*0.2,17640))<=45012.6,MAX(0,B30-MIN(B30*0.2,17640))*0.15-4679.03,IF(MAX(0,B30-MIN(B30*0.2,17640))<=55976.16,MAX(0,B30-MIN(B30*0.2,17640))*0.225-8054.97,MAX(0,B30-MIN(B30*0.2,17640))*0.275-10853.78)))),IF(B30<=28467.2,0,IF(B30<=33919.8,B30*0.075-2135.04,IF(B30<=45012.6,B30*0.15-4679.03,IF(B30<=55976.16,B30*0.225-8054.97,B30*0.275-10853.78))))))
B31: =E20 + IF('RESULTADO DETALHADO'!B78 = "ARBITRAMENTO",'RESULTADO DETALHADO'!D75 * 0.2, MAX(0,'RESULTADO DETALHADO'!D77 - RESULTADO!G56)) + PARTICULAR!O33 | C31: =C20 | D31: =IF(B31 < 600000, 0, IF(B31 > 1200000, 10%, ((B31/60000)-10)/100)) | E31: =B31*D31 | F31: =MAX(E31,MIN(IF(MAX(0,B31-MIN(B31*0.2,17640))<=28467.2,0,IF(MAX(0,B31-MIN(B31*0.2,17640))<=33919.8,MAX(0,B31-MIN(B31*0.2,17640))*0.075-2135.04,IF(MAX(0,B31-MIN(B31*0.2,17640))<=45012.6,MAX(0,B31-MIN(B31*0.2,17640))*0.15-4679.03,IF(MAX(0,B31-MIN(B31*0.2,17640))<=55976.16,MAX(0,B31-MIN(B31*0.2,17640))*0.225-8054.97,MAX(0,B31-MIN(B31*0.2,17640))*0.275-10853.78)))),IF(B31<=28467.2,0,IF(B31<=33919.8,B31*0.075-2135.04,IF(B31<=45012.6,B31*0.15-4679.03,IF(B31<=55976.16,B31*0.225-8054.97,B31*0.275-10853.78))))))
B32: =E21 + IF('RESULTADO DETALHADO'!B87 = "ARBITRAMENTO",'RESULTADO DETALHADO'!D84 * 0.2, MAX(0,'RESULTADO DETALHADO'!D86 - RESULTADO!G57)) + PARTICULAR!O37 | C32: =C21 | D32: =IF(B32 < 600000, 0, IF(B32 > 1200000, 10%, ((B32/60000)-10)/100)) | E32: =B32*D32 | F32: =MAX(E32,MIN(IF(MAX(0,B32-MIN(B32*0.2,17640))<=28467.2,0,IF(MAX(0,B32-MIN(B32*0.2,17640))<=33919.8,MAX(0,B32-MIN(B32*0.2,17640))*0.075-2135.04,IF(MAX(0,B32-MIN(B32*0.2,17640))<=45012.6,MAX(0,B32-MIN(B32*0.2,17640))*0.15-4679.03,IF(MAX(0,B32-MIN(B32*0.2,17640))<=55976.16,MAX(0,B32-MIN(B32*0.2,17640))*0.225-8054.97,MAX(0,B32-MIN(B32*0.2,17640))*0.275-10853.78)))),IF(B32<=28467.2,0,IF(B32<=33919.8,B32*0.075-2135.04,IF(B32<=45012.6,B32*0.15-4679.03,IF(B32<=55976.16,B32*0.225-8054.97,B32*0.275-10853.78))))))
C33: TOTAL | F33: =SUM(F25:F32)
A36: VENDAS PJ
A37: PJ | B37: JANEIRO | C37: FEVEREIRO | D37: MARÇO | E37: ABRIL | F37: MAIO | G37: JUNHO | H37: JULHO | I37: AGOSTO | J37: SETEMBRO | K37: OUTUBRO | L37: NOVEMBRO | M37: DEZEMBRO | N37: TOTAL
A38: RECEITA | B38: =SUMIFS(RECEITAS!$I:$I,RECEITAS!$D:$D,"PJ",RECEITAS!$F:$F,(LEFT(IRPFM!B$37,3))) | C38: =SUMIFS(RECEITAS!$I:$I,RECEITAS!$D:$D,"PJ",RECEITAS!$F:$F,(LEFT(IRPFM!C$37,3))) | D38: =SUMIFS(RECEITAS!$I:$I,RECEITAS!$D:$D,"PJ",RECEITAS!$F:$F,(LEFT(IRPFM!D$37,3))) | E38: =SUMIFS(RECEITAS!$I:$I,RECEITAS!$D:$D,"PJ",RECEITAS!$F:$F,(LEFT(IRPFM!E$37,3))) | F38: =SUMIFS(RECEITAS!$I:$I,RECEITAS!$D:$D,"PJ",RECEITAS!$F:$F,(LEFT(IRPFM!F$37,3))) | G38: =SUMIFS(RECEITAS!$I:$I,RECEITAS!$D:$D,"PJ",RECEITAS!$F:$F,(LEFT(IRPFM!G$37,3))) | H38: =SUMIFS(RECEITAS!$I:$I,RECEITAS!$D:$D,"PJ",RECEITAS!$F:$F,(LEFT(IRPFM!H$37,3))) | I38: =SUMIFS(RECEITAS!$I:$I,RECEITAS!$D:$D,"PJ",RECEITAS!$F:$F,(LEFT(IRPFM!I$37,3))) | ... M38: =SUMIFS(RECEITAS!$I:$I,RECEITAS!$D:$D,"PJ",RECEITAS!$F:$F,(LEFT(IRPFM!M$37,3))) | N38: =SUM(B38:M38)
A39: DESPESAS | B39: =$E$8/12 | C39: =$E$8/12 | D39: =$E$8/12 | E39: =$E$8/12 | F39: =$E$8/12 | G39: =$E$8/12 | H39: =$E$8/12 | I39: =$E$8/12 | ... M39: =$E$8/12 | N39: =SUM(B39:M39)
A40: IMPOSTO | B40: =(B38/$E$5)*$E$6 | C40: =(C38/$E$5)*$E$6 | D40: =(D38/$E$5)*$E$6 | E40: =(E38/$E$5)*$E$6 | F40: =(F38/$E$5)*$E$6 | G40: =(G38/$E$5)*$E$6 | H40: =(H38/$E$5)*$E$6 | I40: =(I38/$E$5)*$E$6 | ... M40: =(M38/$E$5)*$E$6 | N40: =SUM(B40:M40)
A41: VALOR A DISTRIBUIR | B41: =IF(B38-B39-B40>0,B38-B39-B40,0) | C41: =IF(C38-C39-C40>0,C38-C39-C40,0) | D41: =IF(D38-D39-D40>0,D38-D39-D40,0) | E41: =IF(E38-E39-E40>0,E38-E39-E40,0) | F41: =IF(F38-F39-F40>0,F38-F39-F40,0) | G41: =IF(G38-G39-G40>0,G38-G39-G40,0) | H41: =IF(H38-H39-H40>0,H38-H39-H40,0) | I41: =IF(I38-I39-I40>0,I38-I39-I40,0) | ... M41: =IF(M38-M39-M40>0,M38-M39-M40,0) | N41: =SUM(B41:M41)
A42: LUCRO ISENTO | B42: =E10 | C42: =IF(B42-B41>0,B42-B41,0) | D42: =IF(C42-C41>0,C42-C41,0) | E42: =IF(D42-D41>0,D42-D41,0) | F42: =IF(E42-E41>0,E42-E41,0) | G42: =IF(F42-F41>0,F42-F41,0) | H42: =IF(G42-G41>0,G42-G41,0) | I42: =IF(H42-H41>0,H42-H41,0) | J42: =IF(I42-I41>0,I42-I41,0) | ... M42: =IF(L42-L41>0,L42-L41,0)
A43: BASE TRIBUTÁVEL | B43: =IF(B41-B42<0,0,B41-B42) | C43: =IF(C41-C42<0,0,C41-C42) | D43: =IF(D41-D42<0,0,D41-D42) | E43: =IF(E41-E42<0,0,E41-E42) | F43: =IF(F41-F42<0,0,F41-F42) | G43: =IF(G41-G42<0,0,G41-G42) | H43: =IF(H41-H42<0,0,H41-H42) | I43: =IF(I41-I42<0,0,I41-I42) | ... M43: =IF(M41-M42<0,0,M41-M42) | N43: =N38-N42
A48: RETENÇÃO NA FONTE 10%
A49: PARCEIRO 1 | B49: JANEIRO | C49: FEVEREIRO | D49: MARÇO | E49: ABRIL | F49: MAIO | G49: JUNHO | H49: JULHO | I49: AGOSTO | J49: SETEMBRO | K49: OUTUBRO | L49: NOVEMBRO | M49: DEZEMBRO | N49: TOTAL
A50: DISTRIBUIÇÃO | B50: =B43*$D$14 | C50: =C43*$D$14 | D50: =D43*$D$14 | E50: =E43*$D$14 | F50: =F43*$D$14 | G50: =G43*$D$14 | H50: =H43*$D$14 | I50: =I43*$D$14 | ... M50: =M43*$D$14 | N50: =SUM(B50:M50)
A51: RETENÇÃO | B51: =IF(B50>50000,B50*10%,0) | C51: =IF(C50>50000,C50*10%,0) | D51: =IF(D50>50000,D50*10%,0) | E51: =IF(E50>50000,E50*10%,0) | F51: =IF(F50>50000,F50*10%,0) | G51: =IF(G50>50000,G50*10%,0) | H51: =IF(H50>50000,H50*10%,0) | I51: =IF(I50>50000,I50*10%,0) | ... M51: =IF(M50>50000,M50*10%,0) | N51: =SUM(B51:M51)
...

Sheet ECONOMIA
B7: CALCIR - ECONOMIA | K7: =RECEITAS!I12
B8: =RECEITAS!B13 | J8: Período Inicial | K8: Período Final
J9: =RECEITAS!H14 | K9: =RECEITAS!I14
B11: RESUMO NEGÓCIO
B13: (+) RECEITA | D13: =RESULTADO!F22+RESULTADO!G39
B14: (-) CUSTOS/DESPESAS | D14: =RESULTADO!F23
B15: (=) RESULTADO | D15: =D13-D14
B16: (-) PREJUÍZO UTILIZADO | D16: =RESULTADO!I58
B17: IMPOSTO PAGO | C17: =IFERROR(D17/D13,0) | D17: =RESULTADO!F36+RESULTADO!F45
B18: ="PREJUÍZO ACUMULADO " & K7+1 | D18: =RESULTADO!G58
B20: ECONOMIA TRIBUTÁRIA
B22: IMPOSTO DE RENDA - Pessoa Física (Exploração exclusivamente pela PF) | D22: =IF(((IF(((D15+RESULTADO!E36)<(D13*0.2)),(D15+RESULTADO!E36)*0.275,D13*0.055))<0),0,IF(((D15+RESULTADO!E36)<(D13*0.2)),((D15+RESULTADO!E36)*0.275),(D13*0.055)))
B23: IMPOSTO DE RENDA - Pessoa Física (Exploração em parceria com a PJ) | D23: =RESULTADO!F36
B24: TRIBUTOS RECOLHIDOS PELA PJ - IRPJ / CSLL / Funrural | D24: =RESULTADO!F45
B26: ECONOMIA TRIBUTÁRIA | D26: =D22-D23-D24
B27: QUAL SERIA A QUANTIA PAGA | D27: =D22-'RESULTADO DETALHADO'!F16 | E27: 1
B28: QUANTO SERÁ PAGO | D28: =D23+D24 | E28: =D28/D27 | F28: =1-E28

Sheet HISTORICO
B7: CALCIR - HISTÓRICO | T7: =RECEITAS!I12
B8: =RECEITAS!B13
B10: 1° REUNIÃO | G10: 2° REUNIÃO | L10: 3° REUNIÃO | Q10: 4° REUNIÃO
B13: Período Inicial | E13: Período Final | G13: Período Inicial | J13: Período Final | L13: Período Inicial | O13: Período Final | Q13: Período Inicial | T13: Período Final
B14: 45658 | E14: 46022 | G14: 45292 | J14: 45657
B17: Descrição | C17: Realizado | D17: Projetado | E17: =CONCAT("Total ",RECEITAS!I12) | G17: Descrição | H17: Realizado | I17: Projetado | J17: =CONCAT("Total ",RECEITAS!N12) | L17: Descrição | M17: Realizado | N17: Projetado | O17: =CONCAT("Total ",RECEITAS!S12) | Q17: Descrição | R17: Realizado | S17: Projetado | T17: =CONCAT("Total ",RECEITAS!X12)
B18: Receitas PF | C18: 0 | D18: 0 | E18: =C18+D18 | G18: Receitas PF | H18: 0 | I18: 0 | J18: =H18+I18 | L18: Receitas PF | O18: =M18+N18 | Q18: Receitas PF | T18: =R18+S18
B20: Despesas Totais PF | C20: =C21+C22 | D20: =D21+D22 | E20: =C20+D20 | G20: Despesas Totais PF | H20: =H21+H22 | I20: =I21+I22 | J20: =H20+I20 | L20: Despesas Totais PF | M20: =M21+M22 | N20: =N21+N22 | O20: =M20+N20 | Q20: Despesas Totais PF | R20: =R21+R22 | S20: =S21+S22 | T20: =R20+S20
B21: Operacionais | E21: =C21+D21 | G21: Operacionais | J21: =H21+I21 | L21: Operacionais | O21: =M21+N21 | Q21: Operacionais | T21: =R21+S21
B22: Imobilizado | E22: =C22+D22 | G22: Imobilizado | J22: =H22+I22 | L22: Imobilizado | O22: =M22+N22 | Q22: Imobilizado | T22: =R22+S22
B24: Resultado PF | C24: =C18-C20 | D24: =D18-D20 | E24: =E18-E20 | G24: Resultado PF | H24: =H18-H20 | I24: =I18-I20 | J24: =J18-J20 | L24: Resultado PF | M24: =M18-M20 | N24: =N18-N20 | O24: =O18-O20 | Q24: Resultado PF | R24: =R18-R20 | S24: =S18-S20 | T24: =T18-T20
B26: Receitas PJ | C26: 0 | D26: 0 | E26: =C26+D26 | G26: Receitas PJ | H26: 0 | I26: 0 | J26: =H26+I26 | L26: Receitas PJ | O26: =M26+N26 | Q26: Receitas PJ | T26: =R26+S26
B28: RESUMO NEGOCIO | G28: RESUMO NEGOCIO | L28: RESUMO NEGOCIO | Q28: RESUMO NEGOCIO
B30: RECEITA | E30: 0 | G30: RECEITA | J30: 0 | L30: RECEITA | Q30: RECEITA
B31: CUSTOS/DESPESAS | E31: 0 | G31: CUSTOS/DESPESAS | J31: 0 | L31: CUSTOS/DESPESAS | Q31: CUSTOS/DESPESAS
B32: RESULTADO | E32: 0 | G32: RESULTADO | J32: 0 | L32: RESULTADO | Q32: RESULTADO
B33: IMPOSTO PAGO | E33: 0 | G33: IMPOSTO PAGO | J33: 0 | L33: IMPOSTO PAGO | Q33: IMPOSTO PAGO
B35: ECONOMIA TRIBUTÁRIA | E35: 0 | G35: ECONOMIA TRIBUTÁRIA | J35: 0 | L35: ECONOMIA TRIBUTÁRIA | Q35: ECONOMIA TRIBUTÁRIA
B40: 5° REUNIÃO | G40: 6° REUNIÃO | L40: 7° REUNIÃO | Q40: 8° REUNIÃO
B43: Período Inicial | E43: Período Final | G43: Período Inicial | J43: Período Final | L43: Período Inicial | O43: Período Final | Q43: Período Inicial | T43: Período Final
B46: Descrição | C46: Realizado | D46: Projetado | E46: =CONCAT("Total ",RECEITAS!I41) | G46: Descrição | H46: Realizado | I46: Projetado | J46: =CONCAT("Total ",RECEITAS!N41) | L46: Descrição | M46: Realizado | N46: Projetado | O46: =CONCAT("Total ",RECEITAS!S41) | Q46: Descrição | R46: Realizado | S46: Projetado | T46: =CONCAT("Total ",RECEITAS!X41)
B47: Receitas PF | E47: =C47+D47 | G47: Receitas PF | J47: =H47+I47 | L47: Receitas PF | O47: =M47+N47 | Q47: Receitas PF | T47: =R47+S47
B49: Despesas Totais PF | C49: =C50+C51 | D49: =D50+D51 | E49: =C49+D49 | G49: Despesas Totais PF | H49: =H50+H51 | I49: =I50+I51 | J49: =J50+J51 | L49: Despesas Totais PF | M49: =M50+M51 | N49: =N50+N51 | O49: =M49+N49 | Q49: Despesas Totais PF | R49: =R50+R51 | S49: =S50+S51 | T49: =R49+S49
B50: Operacionais | E50: =C50+D50 | G50: Operacionais | J50: =H50+I50 | L50: Operacionais | O50: =M50+N50 | Q50: Operacionais | T50: =R50+S50
B51: Imobilizado | E51: =C51+D51 | G51: Imobilizado | J51: =H51+I51 | L51: Imobilizado | O51: =M51+N51 | Q51: Imobilizado | T51: =R51+S51
B53: Resultado PF | C53: =C47-C49 | D53: =D47-D49 | E53: =E47-E49 | G53: Resultado PF | H53: =H47-H49 | I53: =I47-I49 | J53: =J47-J49 | L53: Resultado PF | M53: =M47-M49 | N53: =N47-N49 | O53: =O47-O49 | Q53: Resultado PF | R53: =R47-R49 | S53: =S47-S49 | T53: =T47-T49
B55: Receitas PJ | E55: =C55+D55 | G55: Receitas PJ | J55: =H55+I55 | L55: Receitas PJ | O55: =M55+N55 | Q55: Receitas PJ | T55: =R55+S55
B57: RESUMO NEGOCIO | G57: RESUMO NEGOCIO | L57: RESUMO NEGOCIO | Q57: RESUMO NEGOCIO
B59: RECEITA | G59: RECEITA | L59: RECEITA | Q59: RECEITA
B60: CUSTOS/DESPESAS | G60: CUSTOS/DESPESAS | L60: CUSTOS/DESPESAS | Q60: CUSTOS/DESPESAS
B61: RESULTADO | G61: RESULTADO | L61: RESULTADO | Q61: RESULTADO
B62: IMPOSTO PAGO | G62: IMPOSTO PAGO | L62: IMPOSTO PAGO | Q62: IMPOSTO PAGO
B64: ECONOMIA TRIBUTÁRIA | G64: ECONOMIA TRIBUTÁRIA | L64: ECONOMIA TRIBUTÁRIA | Q64: ECONOMIA TRIBUTÁRIA
B68: 9° REUNIÃO | G68: 10° REUNIÃO | L68: 11° REUNIÃO | Q68: 12° REUNIÃO
B71: Período Inicial | E71: Período Final | G71: Período Inicial | J71: Período Final | L71: Período Inicial | O71: Período Final | Q71: Período Inicial | T71: Período Final
B74: Descrição | C74: Realizado | D74: Projetado | E74: =CONCAT("Total ",RECEITAS!I69) | G74: Descrição | H74: Realizado | I74: Projetado | J74: =CONCAT("Total ",RECEITAS!N69) | L74: Descrição | M74: Realizado | N74: Projetado | O74: =CONCAT("Total ",RECEITAS!S69) | Q74: Descrição | R74: Realizado | S74: Projetado | T74: =CONCAT("Total ",RECEITAS!X69)
B75: Receitas PF | E75: =C75+D75 | G75: Receitas PF | J75: =H75+I75 | L75: Receitas PF | O75: =M75+N75 | Q75: Receitas PF | T75: =R75+S75
B77: Despesas Totais PF | C77: =C78+C79 | D77: =D78+D79 | E77: =C77+D77 | G77: Despesas Totais PF | H77: =H78+H79 | I77: =I78+I79 | J77: =H77+I77 | L77: Despesas Totais PF | M77: =M78+M79 | N77: =N78+N79 | O77: =M77+N77 | Q77: Despesas Totais PF | R77: =R78+R79 | S77: =S78+S79 | T77: =R77+S77
B78: Operacionais | E78: =C78+D78 | G78: Operacionais | J78: =H78+I78 | L78: Operacionais | O78: =M78+N78 | Q78: Operacionais | T78: =R78+S78
B79: Imobilizado | E79: =C79+D79 | G79: Imobilizado | J79: =H79+I79 | L79: Imobilizado | O79: =M79+N79 | Q79: Imobilizado | T79: =R79+S79
...

Sheet ESTOQUE
B6: CALCIR - ESTOQUES | G6: =RECEITAS!I12
B7: =RECEITAS!B13 | F7: Período Inicial | G7: Período Final
F8: =RECEITAS!H14 | G8: =RECEITAS!I14
B10: SAFRA ANTERIOR
B11: PRODUTO | D11: PRODUÇÃO | F11: PREÇO MÉDIO | G11: TOTAL
B25: SAFRA ATUAL
B26: PRODUTO | C26: AREA | D26: PRODUTIVIDADE | E26: PRODUÇÃO | F26: PREÇO MÉDIO | G26: TOTAL
B40: GRÃOS RECEBIDOS
B41: PRODUTO | D41: PRODUTIVIDADE | F41: PREÇO MÉDIO | G41: TOTAL

Sheet QUITAÇÃO
B2: CONTROLE DE PRODUÇÃO
B3: =RECEITAS!B13
B5: Período Inicial | C5: Período Final
B6: =RECEITAS!H14 | C6: =RECEITAS!I14
B8: TABELA PARA TRANSFERÊNCIA DE PRODUTOS, CONFORME PERCENTUAL ESTIPULADO NO CONTRATO DE PARCERIA ENTRE PF X PJ
B10: CULTURAS | C10: ÁREA | D10: PRODUTIVIDADE | E10: PRODUÇÃO | F10: 0.8 | G10: 0.2 | H10: PREÇO | I10: TOTAL | J10: PRODUTO | K10: % | L10: EQUIVALÊNCIA | M10: VENDAS | N10: SALDO
B11: ARROZ | D11: =E11/C11 | F11: =E11*$F$10 | G11: =E11*$G$10 | I11: =G11*H11 | J11: soja | L11: =($I$14/H11)*K11 | N11: =L11-M11
B12: SOJA | D12: =E12/C12 | F12: =E12*$F$10 | G12: =E12*$G$10 | I12: =G12*H12 | J12: soja | L12: =($I$14/H12)*K12 | N12: =L12-M12
B13: PECUÁRIA | D13: =E13/C13 | F13: =E13*$F$10 | G13: =E13*$G$10 | I13: =G13*H13 | J13: soja | L13: =($I$14/H13)*K13 | N13: =L13-M13
B14: TOTAL | C14: =SUM(C11:C13) | I14: =SUM(I11:I13) | K14: =SUM(K11:K13) | L14: =SUM(L11:L13) | M14: =SUM(M11:M13) | N14: =SUM(N11:N13)
B15: (*) Na produção total, considerar apenas o que foi colhido nas áreas próprias e que estão incorporadas na Pessoa Jurídica.
K16: ADIANTAMENTO SAFRAS ANTERIORES
K17: CRÉDITO SAFRAS ANTERIORES
B18: Cotações: | M18: SOJA A VENDER PJ | N18: =N14-N16+N17
B19: TOTAL ÁREA PF (HA)
B20: TOTAL ÁREA PJ (HA)
B21: PARCERIA PJ X PF | C21: 0.2

Sheet PJ-
E1: PREJUÍZO À COMPENSAR
D2: =ABS(#REF!) | E2: =-D2
D3: =ABS(#REF!) | E3: =-D3
D4: =ABS(#REF!) | E4: =-D4
D5: =ABS(#REF!) | E5: =-D5
D6: =ABS(#REF!) | E6: =-D6
D7: =ABS(#REF!) | E7: =-D7
D8: =ABS(#REF!) | E8: =-D8
D9: =ABS(#REF!) | E9: =-D9
E10: =SUM(E2:E6)
B12: SIMULAÇÃO | G12: =RECEITAS!I12
B13: =RECEITAS!B13
B15: Quantidade de meses analisados | C15: 12
B16: Total faturado (s/ PIS e Cofins) | C16: 0
B17: Total faturado (c/ PIS e Cofins) | C17: 0
B18: Receitas com Aluguéis
B19: Receitas Financeiras | E19: Total tributos PJ | F19: =IF(C15=0,"ERRO",SUM(C23:C28))
B20: Receitas Não Operacionais | E20: Tributos PJ + Dif. Funrural | F20: =IF(C15=0,"ERRO",SUM(C23:C25,C27,C28,C30))
B21: Base de Cálculo IR | C21: =((C16+C17)*0.08)+(C18*0.32)+C19+C20
B22: Base de Cálculo CSLL | C22: =((C16+C17)*0.12)+(C18*0.32)+C19+C20
B23: IR - 15% (1,20%) | C23: =C21*0.15
B24: IR Adicional - 10% (0,8%) | C24: =IF(C21>C15*20000,(C21-C15*20000)*0.1,0)
B25: CSLL - 9% (1,08%) | C25: =C22*0.09
B26: Funrural - 2,05% | C26: =(C16+C17)*2.05/100
B27: PIS | C27: =(C17+C18)*0.65/100
B28: Cofins | C28: =(C17+C18)*3/100
B30: Diferença de Funrural - 0,55% | C30: =(C16+C17)*0.55/100
B50: CLIENTE
B52: SIMULAÇÃO

Sheet Cálculo Imposto PJ
B1: APURAÇÃO DE IMPOSTOS PESSOA JURÍDICA | P1: =RECEITAS!I12 | Q1: =RECEITAS!J12
B2: =RECEITAS!B13
B4: Mês | C4: FATURAMENTO RECEITA | D4: FUNRURAL REGIME DE COMPETÊNCIA | E4: FATURAMENTO RECEBIDO | F4: PIS SUSPENSO/ISENTO | G4: COFINS SUSPENSO/ISENTO | H4: VALOR TOTAL TRIMESTRE | I4: GANHO VENDA IMOBILIZADO / APLICAÇÃO FINANCEIRA | J4: IRPJ E CSLL REGIME DE CAIXA
J5: BASE CÁLCULO IPRJ 8% | K5: IPRJ 15% CÓDIGO: 2089 | L5: Excedente R$ 60 MIL da base de cálculo IPRJ | M5: ADICIONAL IPRJ 10% | N5: IPRJ A RECOLHER CÓDIGO: 2089 + ADICONAL | O5: BASE CÁLCULO CSLL 12% | P5: CSLL 9% CÓDIGO: 2372 | Q5: NOVO ADICIONAL 10%
B6: JAN | C6: =SUMIFS(RECEITAS!$I:$I, RECEITAS!$F:$F, B6, RECEITAS!$D:$D, "PJ") | D6: =C6*2.05% | E6: =C6 | H6: =SUM(C6:C8) | I6: 0 | J6: =H6*8%+I6 | K6: =J6*15% | L6: =IF(J6>60000,J6-60000,0) | N6: =K6+M6 | O6: =H6*12%+I6 | P6: =O6*9% | Q6: =IF(H6 > 1250000,H6 * 0.1, 0)
B7: FEV | C7: =SUMIFS(RECEITAS!$I:$I, RECEITAS!$F:$F, B7, RECEITAS!$D:$D, "PJ") | D7: =C7*2.05% | E7: =C7 | M7: =IF(J6 > 60000, (J6 - 60000) * 0.1, 0)
B8: MAR | C8: =SUMIFS(RECEITAS!$I:$I, RECEITAS!$F:$F, B8, RECEITAS!$D:$D, "PJ") | D8: =C8*2.05% | E8: =C8
B9: ABR | C9: =SUMIFS(RECEITAS!$I:$I, RECEITAS!$F:$F, B9, RECEITAS!$D:$D, "PJ") | D9: =C9*2.05% | E9: =C9 | H9: =SUM(C9:C11) | I9: 0 | J9: =H9*8%+I9 | K9: =J9*15% | L9: =IF(J9>60000,J9-60000,0) | M9: =IF(J9 > 60000, (J9 - 60000) * 0.1, 0) | N9: =K9+M9 | O9: =H9*12%+I9 | P9: =O9*9% | Q9: =IF(H9 > 1250000, H9 * 0.1, 0)
B10: MAI | C10: =SUMIFS(RECEITAS!$I:$I, RECEITAS!$F:$F, B10, RECEITAS!$D:$D, "PJ") | D10: =C10*2.05% | E10: =C10
B11: JUN | C11: =SUMIFS(RECEITAS!$I:$I, RECEITAS!$F:$F, B11, RECEITAS!$D:$D, "PJ") | D11: =C11*2.05% | E11: =C11
B12: JUL | C12: =SUMIFS(RECEITAS!$I:$I, RECEITAS!$F:$F, B12, RECEITAS!$D:$D, "PJ") | D12: =C12*2.05% | E12: =C12 | H12: =SUM(C12:C14) | J12: =H12*8%+I12 | K12: =J12*15% | L12: =IF(J12>60000,J12-60000,0) | M12: =L12*10% | N12: =K12+M12 | O12: =H12*12%+I12 | P12: =O12*9% | Q12: =IF(H12 > 1250000,H12 * 0.1, 0)
B13: AGO | C13: =SUMIFS(RECEITAS!$I:$I, RECEITAS!$F:$F, B13, RECEITAS!$D:$D, "PJ") | D13: =C13*2.05% | E13: =C13
B14: SET | C14: =SUMIFS(RECEITAS!$I:$I, RECEITAS!$F:$F, B14, RECEITAS!$D:$D, "PJ") | D14: =C14*2.05% | E14: =C14
B15: OUT | C15: =SUMIFS(RECEITAS!$I:$I, RECEITAS!$F:$F, B15, RECEITAS!$D:$D, "PJ") | D15: =C15*2.05% | E15: =C15 | H15: =SUM(C15:C17) | I15: 0 | J15: =H15*8%+I15 | K15: =J15*15% | L15: =IF(J15>60000,J15-60000,0) | M15: =L15*10% | N15: =K15+M15 | O15: =H15*12%+I15 | P15: =O15*9% | Q15: =IF(H15 > 1250000,H15 * 0.1, 0)
B16: NOV | C16: =SUMIFS(RECEITAS!$I:$I, RECEITAS!$F:$F, B16, RECEITAS!$D:$D, "PJ") | D16: =C16*2.05% | E16: =C16
B17: DEZ | C17: =SUMIFS(RECEITAS!$I:$I, RECEITAS!$F:$F, B17, RECEITAS!$D:$D, "PJ") | D17: =C17*2.05% | E17: =C17
B18: TOTAL | C18: =SUM(C6:C17) | D18: =SUM(D6:D17) | E18: =SUM(E6:E17) | F18: =SUM(F6:F17) | G18: =SUM(G6:G17) | H18: =SUM(H6:H17) | I18: =SUM(I6:I17) | J18: =SUM(J6:J17) | ... Q18: =SUM(Q6:Q17)
C20: RECEITA | F20: IRPJ | H20: FUNRURAL | K20: IRPJ | N20: CSLL
C21: =C18 | F21: 0 | K21: =N18 | N21: =P18
N24: Valores apurados | O24: =F21+K21+N21

Sheet Controle de Estoque
B1: Controle de Estoque de Grãos
E3: Período Inicial | F3: Período Final
B5: ARROZ | C5: Até
B6: ESTOQUE INICIAL | C6: 0 | D6: COLHEITA 2020/21 | E6: VENDA | F6: ESTOQUE FINAL
D7: 0 | E7: 0 | F7: =C6+D7-E7
F8: =F7+D8-E8
F9: =F8+D9-E9
F10: =F9+D10-E10
F11: =F10+D11-E11
F12: =F11+D12-E12
F13: =F12+D13-E13
